<?xml version='1.0' encoding='utf-8'?>
<mujoco model="adam_pro">
  <compiler angle="radian" meshdir="meshes_stl_0.25/" />
  <asset>
    <mesh name="pelvis" file="pelvis.STL" />
    <mesh name="hipPitchLeft" file="hipPitchLeft.STL" />
    <mesh name="hipRollLeft" file="hipRollLeft.STL" />
    <mesh name="thighLeft" file="thighLeft.STL" />
    <mesh name="shinLeft" file="shinLeft.STL" />
    <mesh name="anklePitchLeft" file="anklePitchLeft.STL" />
    <mesh name="toeLeft" file="toeLeft.STL" />
    <mesh name="hipPitchRight" file="hipPitchRight.STL" />
    <mesh name="hipRollRight" file="hipRollRight.STL" />
    <mesh name="thighRight" file="thighRight.STL" />
    <mesh name="shinRight" file="shinRight.STL" />
    <mesh name="anklePitchRight" file="anklePitchRight.STL" />
    <mesh name="toeRight" file="toeRight.STL" />
    <mesh name="waistRoll_link" file="waistRoll_link.STL" />
    <mesh name="waistPitch_link" file="waistPitch_link.STL" />
    <mesh name="torso" file="torso.STL" />
    <mesh name="shoulderPitchLeft" file="shoulderPitchLeft.STL" />
    <mesh name="shoulderRollLeft" file="shoulderRollLeft.STL" />
    <mesh name="shoulderYawLeft" file="shoulderYawLeft.STL" />
    <mesh name="elbowLeft" file="elbowLeft.STL" />
    <mesh name="wristYawLeft" file="wristYawLeft.STL" />
    <mesh name="wristPitchLeft" file="wristPitchLeft.STL" />
    <mesh name="wristRollLeft" file="wristRollLeft.STL" />
    <mesh name="L_thumb_proximal_base" file="L_thumb_proximal_base.STL" />
    <mesh name="L_thumb_proximal" file="L_thumb_proximal.STL" />
    <mesh name="L_thumb_intermediate" file="L_thumb_intermediate.STL" />
    <mesh name="L_thumb_distal" file="L_thumb_distal.STL" />
    <mesh name="L_index_proximal" file="L_index_proximal.STL" />
    <mesh name="L_index_distal" file="L_index_distal.STL" />
    <mesh name="L_middle_proximal" file="L_middle_proximal.STL" />
    <mesh name="L_middle_distal" file="L_middle_distal.STL" />
    <mesh name="L_ring_proximal" file="L_ring_proximal.STL" />
    <mesh name="L_ring_distal" file="L_ring_distal.STL" />
    <mesh name="L_pinky_proximal" file="L_pinky_proximal.STL" />
    <mesh name="L_pinky_distal" file="L_pinky_distal.STL" />
    <mesh name="shoulderPitchRight" file="shoulderPitchRight.STL" />
    <mesh name="shoulderRollRight" file="shoulderRollRight.STL" />
    <mesh name="shoulderYawRight" file="shoulderYawRight.STL" />
    <mesh name="elbowRight" file="elbowRight.STL" />
    <mesh name="wristYawRight" file="wristYawRight.STL" />
    <mesh name="wristPitchRight" file="wristPitchRight.STL" />
    <mesh name="wristRollRight" file="wristRollRight.STL" />
    <mesh name="R_thumb_proximal_base" file="R_thumb_proximal_base.STL" />
    <mesh name="R_thumb_proximal" file="R_thumb_proximal.STL" />
    <mesh name="R_thumb_intermediate" file="R_thumb_intermediate.STL" />
    <mesh name="R_thumb_distal" file="R_thumb_distal.STL" />
    <mesh name="R_index_proximal" file="R_index_proximal.STL" />
    <mesh name="R_index_distal" file="R_index_distal.STL" />
    <mesh name="R_middle_proximal" file="R_middle_proximal.STL" />
    <mesh name="R_middle_distal" file="R_middle_distal.STL" />
    <mesh name="R_ring_proximal" file="R_ring_proximal.STL" />
    <mesh name="R_ring_distal" file="R_ring_distal.STL" />
    <mesh name="R_pinky_proximal" file="R_pinky_proximal.STL" />
    <mesh name="R_pinky_distal" file="R_pinky_distal.STL" />
    <mesh name="neckYaw_link" file="neckYaw_link.STL" />
    <mesh name="neckPitch_link" file="neckPitch_link.STL" />
  </asset>
  <worldbody>
    <body name="pelvis" pos="0 0 0.95">
      <inertial pos="-0.00034724 0 -0.00735759" quat="0.502838 0.502859 -0.497127 0.497143" mass="10.3565" diaginertia="0.0687803 0.0621174 0.0345151" />
      <joint name="floating_base" type="free" limited="false" actuatorfrclimited="false" />
      <geom type="mesh" contype="0" conaffinity="0" group="1" density="0" rgba="0.752941 0.752941 0.752941 1" mesh="pelvis" />
      <geom type="mesh" rgba="0.752941 0.752941 0.752941 1" mesh="pelvis" />
      <body name="hipPitchLeft" pos="0 0.0961925 -0.0332412" quat="0.953717 -0.300706 0 0">
        <inertial pos="-0.0566022 0.0576144 -0.00077159" quat="-0.0505313 0.548334 -0.448358 0.704097" mass="2.2338" diaginertia="0.00520115 0.00510328 0.00286381" />
        <joint name="hipPitch_Left" pos="0 0 0" axis="0 1 0" range="-2.164 2.164" actuatorfrcrange="-230 230" />
        <geom type="mesh" contype="0" conaffinity="0" group="1" density="0" rgba="0.752941 0.752941 0.752941 1" mesh="hipPitchLeft" />
        <geom type="mesh" rgba="0.752941 0.752941 0.752941 1" mesh="hipPitchLeft" />
        <body name="hipRollLeft" pos="-0.0255 0.069 0" quat="0.953717 0.300706 0 0">
          <inertial pos="0.0392416 4.107e-05 -0.0103292" quat="0.0275849 0.82035 0.0241895 0.570683" mass="1.35108" diaginertia="0.00141452 0.00129056 0.00119603" />
          <joint name="hipRoll_Left" pos="0 0 0" axis="1 0 0" range="-0.733 1.605" actuatorfrcrange="-160 160" />
          <geom type="mesh" contype="0" conaffinity="0" group="1" density="0" rgba="0.752941 0.752941 0.752941 1" mesh="hipRollLeft" />
          <geom type="mesh" rgba="0.752941 0.752941 0.752941 1" mesh="hipRollLeft" />
          <body name="thighLeft" pos="0.044 0 -0.0525">
            <inertial pos="0.00244052 -0.00866423 -0.134336" quat="0.711611 -0.0492483 0.0272749 0.700315" mass="6.43433" diaginertia="0.0639418 0.0583116 0.0126694" />
            <joint name="hipYaw_Left" pos="0 0 0" axis="0 0 1" range="-0.785 0.785" actuatorfrcrange="-105 105" />
            <geom type="mesh" contype="0" conaffinity="0" group="1" density="0" rgba="0.752941 0.752941 0.752941 1" mesh="thighLeft" />
            <geom type="mesh" rgba="0.752941 0.752941 0.752941 1" mesh="thighLeft" />
            <body name="shinLeft" pos="0 -0.0355 -0.369">
              <inertial pos="-0.00053135 0.00081959 -0.145381" quat="0.788039 0.00408898 0.00696215 0.615572" mass="2.25363" diaginertia="0.0215921 0.0215141 0.00136466" />
              <joint name="kneePitch_Left" pos="0 0 0" axis="0 1 0" range="0.052 2.391" actuatorfrcrange="-230 230" />
              <geom type="mesh" contype="0" conaffinity="0" group="1" density="0" rgba="0.752941 0.752941 0.752941 1" mesh="shinLeft" />
              <geom type="mesh" rgba="0.752941 0.752941 0.752941 1" mesh="shinLeft" />
              <body name="anklePitchLeft" pos="0 0 -0.37">
                <inertial pos="0 0 0" mass="0.0301423" diaginertia="3.14e-06 3.14e-06 2.04e-06" />
                <joint name="anklePitch_Left" pos="0 0 0" axis="0 1 0" range="-1 0.35" actuatorfrcrange="-40 40" />
                <geom type="mesh" contype="0" conaffinity="0" group="1" density="0" rgba="1 1 1 1" mesh="anklePitchLeft" />
                <geom type="mesh" rgba="1 1 1 1" mesh="anklePitchLeft" />
                <body name="toeLeft">
                  <inertial pos="0.0374997 -4.016e-05 -0.0419674" quat="-0.0209271 0.743591 -0.0168677 0.668094" mass="0.634796" diaginertia="0.00233488 0.00226889 0.000434699" />
                  <joint name="ankleRoll_Left" pos="0 0 0" axis="1 0 0" range="-0.3491 0.3491" actuatorfrcrange="-12 12" />
                  <geom type="mesh" contype="0" conaffinity="0" group="1" density="0" rgba="0.752941 0.752941 0.752941 1" mesh="toeLeft" />
                  <geom size="0.12 0.05 0.01" pos="0.05 0 -0.055" type="box" rgba="0.752941 0.752941 0.752941 1" />
                </body>
              </body>
            </body>
          </body>
        </body>
      </body>
      <body name="hipPitchRight" pos="0 -0.0961925 -0.0332412" quat="0.953717 0.300706 0 0">
        <inertial pos="-0.0566179 -0.0575934 -0.00078211" quat="0.0466125 0.551069 0.444978 0.704376" mass="2.23477" diaginertia="0.00520391 0.00510426 0.00286722" />
        <joint name="hipPitch_Right" pos="0 0 0" axis="0 1 0" range="-2.164 2.164" actuatorfrcrange="-230 230" />
        <geom type="mesh" contype="0" conaffinity="0" group="1" density="0" rgba="0.752941 0.752941 0.752941 1" mesh="hipPitchRight" />
        <geom type="mesh" rgba="0.752941 0.752941 0.752941 1" mesh="hipPitchRight" />
        <body name="hipRollRight" pos="-0.0255 -0.069 0" quat="0.953717 -0.300706 0 0">
          <inertial pos="0.0392598 -5.814e-05 -0.0103241" quat="-0.02931 0.821547 -0.0263648 0.568776" mass="1.3517" diaginertia="0.00141668 0.00129138 0.00119538" />
          <joint name="hipRoll_Right" pos="0 0 0" axis="1 0 0" range="-1.605 0.733" actuatorfrcrange="-160 160" />
          <geom type="mesh" contype="0" conaffinity="0" group="1" density="0" rgba="0.752941 0.752941 0.752941 1" mesh="hipRollRight" />
          <geom type="mesh" rgba="0.752941 0.752941 0.752941 1" mesh="hipRollRight" />
          <body name="thighRight" pos="0.044 0 -0.0525">
            <inertial pos="0.00245598 0.00865064 -0.134332" quat="0.700408 0.0274534 -0.0491764 0.711517" mass="6.43084" diaginertia="0.0639169 0.0582708 0.0126767" />
            <joint name="hipYaw_Right" pos="0 0 0" axis="0 0 1" range="-0.785 0.785" actuatorfrcrange="-105 105" />
            <geom type="mesh" contype="0" conaffinity="0" group="1" density="0" rgba="0.752941 0.752941 0.752941 1" mesh="thighRight" />
            <geom type="mesh" rgba="0.752941 0.752941 0.752941 1" mesh="thighRight" />
            <body name="shinRight" pos="0 0.0355 -0.369">
              <inertial pos="-0.00052844 -0.00082152 -0.145334" quat="0.619488 0.00695186 0.00407547 0.784965" mass="2.25459" diaginertia="0.0215721 0.021496 0.00136482" />
              <joint name="kneePitch_Right" pos="0 0 0" axis="0 1 0" range="0.052 2.391" actuatorfrcrange="-230 230" />
              <geom type="mesh" contype="0" conaffinity="0" group="1" density="0" rgba="0.752941 0.752941 0.752941 1" mesh="shinRight" />
              <geom type="mesh" rgba="0.752941 0.752941 0.752941 1" mesh="shinRight" />
              <body name="anklePitchRight" pos="0 0 -0.37">
                <inertial pos="0 0 0" mass="0.0301423" diaginertia="3.14e-06 3.14e-06 2.04e-06" />
                <joint name="anklePitch_Right" pos="0 0 0" axis="0 1 0" range="-1 0.35" actuatorfrcrange="-40 40" />
                <geom type="mesh" contype="0" conaffinity="0" group="1" density="0" rgba="1 1 1 1" mesh="anklePitchRight" />
                <geom type="mesh" rgba="1 1 1 1" mesh="anklePitchRight" />
                <body name="toeRight">
                  <inertial pos="0.0375023 4.002e-05 -0.0419671" quat="0.0209768 0.743592 0.0169235 0.66809" mass="0.634808" diaginertia="0.00233489 0.00226889 0.000434726" />
                  <joint name="ankleRoll_Right" pos="0 0 0" axis="1 0 0" range="-0.3491 0.3491" actuatorfrcrange="-12 12" />
                  <geom type="mesh" contype="0" conaffinity="0" group="1" density="0" rgba="0.752941 0.752941 0.752941 1" mesh="toeRight" />
                  <geom size="0.12 0.05 0.01" pos="0.05 0 -0.055" type="box" rgba="0.752941 0.752941 0.752941 1" />
                </body>
              </body>
            </body>
          </body>
        </body>
      </body>
      <body name="waistRoll_link" pos="0 0 0.044">
        <inertial pos="0.00093826 0.00093832 0.0399999" quat="0.920274 -0.012433 -0.0050157 0.391045" mass="2.36268" diaginertia="0.00543214 0.00543129 0.00184735" />
        <joint name="waistRoll" pos="0 0 0" axis="1 0 0" range="-0.279 0.279" actuatorfrcrange="-110 110" />
        <geom type="mesh" contype="0" conaffinity="0" group="1" density="0" rgba="1 1 1 1" mesh="waistRoll_link" />
        <geom type="mesh" rgba="1 1 1 1" mesh="waistRoll_link" />
        <body name="waistPitch_link" pos="0 0 0.08">
          <inertial pos="-8.401e-05 0.00189362 0.0254832" quat="0.480284 0.467519 -0.524152 0.525374" mass="0.563538" diaginertia="0.0015597 0.00151436 0.000672504" />
          <joint name="waistPitch" pos="0 0 0" axis="0 1 0" range="-0.663 1.361" actuatorfrcrange="-110 110" />
          <geom type="mesh" contype="0" conaffinity="0" group="1" density="0" rgba="0.752941 0.752941 0.752941 1" mesh="waistPitch_link" />
          <geom type="mesh" rgba="0.752941 0.752941 0.752941 1" mesh="waistPitch_link" />
          <body name="torso" pos="0 0.0005 0.053">
            <inertial pos="-0.00183601 0.00056583 0.166624" quat="0.999452 -0.00189053 -0.0328345 0.00382224" mass="12.7334" diaginertia="0.13029 0.0859386 0.0736823" />
            <joint name="waistYaw" pos="0 0 0" axis="0 0 1" range="-0.829 0.829" actuatorfrcrange="-110 110" />
            <geom type="mesh" contype="0" conaffinity="0" group="1" density="0" rgba="0.752941 0.752941 0.752941 1" mesh="torso" />
            <geom type="mesh" rgba="0.752941 0.752941 0.752941 1" mesh="torso" />
            <body name="shoulderPitchLeft" pos="0 0.165094 0.25923" quat="0.984808 0.173648 0 0">
              <inertial pos="0.00542694 0.0268987 0.00010792" quat="-0.0545235 0.707235 0.0545271 0.702761" mass="0.216148" diaginertia="0.000380648 0.000322754 0.000187228" />
              <joint name="shoulderPitch_Left" pos="0 0 0" axis="0 1 0" range="-3.613 2.042" actuatorfrcrange="-65 65" />
              <geom type="mesh" contype="0" conaffinity="0" group="1" density="0" rgba="1 1 1 1" mesh="shoulderPitchLeft" />
              <geom type="mesh" rgba="1 1 1 1" mesh="shoulderPitchLeft" />
              <body name="shoulderRollLeft" pos="0.0362 0.0435 0" quat="0.984808 -0.173648 0 0">
                <inertial pos="-0.0343733 0.00962154 -0.0154456" quat="0.942019 0.255487 0.0666284 -0.207093" mass="1.07882" diaginertia="0.00167363 0.00165995 0.000668084" />
                <joint name="shoulderRoll_Left" pos="0 0 0" axis="1 0 0" range="-0.628 2.793" actuatorfrcrange="-65 65" />
                <geom type="mesh" contype="0" conaffinity="0" group="1" density="0" rgba="0.752941 0.752941 0.752941 1" mesh="shoulderRollLeft" />
                <geom type="mesh" rgba="0.752941 0.752941 0.752941 1" mesh="shoulderRollLeft" />
                <body name="shoulderYawLeft" pos="-0.0362 0.034 -0.0797">
                  <inertial pos="-0.00051421 -0.00044442 -0.0619328" quat="0.999912 -0.00948825 0.00877343 0.00302026" mass="0.90142" diaginertia="0.00328641 0.0031732 0.000574119" />
                  <joint name="shoulderYaw_Left" pos="0 0 0" axis="0 0 1" range="-2.583 2.583" actuatorfrcrange="-65 65" />
                  <geom type="mesh" contype="0" conaffinity="0" group="1" density="0" rgba="1 1 1 1" mesh="shoulderYawLeft" />
                  <geom type="mesh" rgba="1 1 1 1" mesh="shoulderYawLeft" />
                  <body name="elbowLeft" pos="0 -0.0285 -0.18295">
                    <inertial pos="-0.0140727 0.0292971 -0.0253473" quat="0.716894 0.14594 0.188043 0.65529" mass="0.917707" diaginertia="0.00110505 0.00109887 0.000457654" />
                    <joint name="elbow_Left" pos="0 0 0" axis="0 1 0" range="-2.496 0.209" actuatorfrcrange="-30 30" />
                    <geom type="mesh" contype="0" conaffinity="0" group="1" density="0" rgba="0.752941 0.752941 0.752941 1" mesh="elbowLeft" />
                    <geom type="mesh" rgba="0.752941 0.752941 0.752941 1" mesh="elbowLeft" />
                    <body name="wristYawLeft" pos="-0.025 0.0285 -0.0729">
                      <inertial pos="-0.00174399 0.0001059 -0.0921606" quat="0.999719 0.00455358 0.00795284 0.0218673" mass="0.955879" diaginertia="0.00254019 0.00248455 0.000526048" />
                      <joint name="wristYaw_Left" pos="0 0 0" axis="0 0 1" range="-2.67 2.67" actuatorfrcrange="-6.4 6.4" />
                      <geom type="mesh" contype="0" conaffinity="0" group="1" density="0" rgba="0.752941 0.752941 0.752941 1" mesh="wristYawLeft" />
                      <geom type="mesh" rgba="0.752941 0.752941 0.752941 1" mesh="wristYawLeft" />
                      <body name="wristPitchLeft" pos="0 0 -0.2017">
                        <inertial pos="-0.00017582 0.00166098 -2.773e-05" quat="0.501712 0.498275 -0.499779 0.500227" mass="0.119635" diaginertia="3.97702e-05 3.35901e-05 2.68997e-05" />
                        <joint name="wristPitch_Left" pos="0 0 0" axis="0 1 0" range="-0.96 0.96" actuatorfrcrange="-6.4 6.4" />
                        <geom type="mesh" contype="0" conaffinity="0" group="1" density="0" rgba="1 1 1 1" mesh="wristPitchLeft" />
                        <geom type="mesh" rgba="1 1 1 1" mesh="wristPitchLeft" />
                        <body name="wristRollLeft">
                          <inertial pos="-0.00027229 0.00864497 -0.0662702" quat="0.670711 0.0163263 -0.0454275 0.740146" mass="0.357497" diaginertia="0.000432574 0.000319196 0.00018278" />
                          <joint name="wristRoll_Left" pos="0 0 0" axis="1 0 0" range="-0.96 0.96" actuatorfrcrange="-6.4 6.4" />
                          <geom type="mesh" contype="0" conaffinity="0" group="1" density="0" rgba="0.752941 0.752941 0.752941 1" mesh="wristRollLeft" />
                          <geom type="mesh" rgba="0.752941 0.752941 0.752941 1" mesh="wristRollLeft" />
                          <body name="L_thumb_proximal_base" pos="0.0245 -0.01 -0.047">
                            <inertial pos="0.00431634 0.00026726 -0.00141885" quat="0.459644 0.663922 0.456556 0.373486" mass="0.0089319" diaginertia="5.7482e-07 4.78268e-07 2.66913e-07" />
                            <joint name="L_thumb_MCP_joint1" pos="0 0 0" axis="0 0 -1" range="0 1.1" actuatorfrcrange="-1 1" />
                            <geom type="mesh" contype="0" conaffinity="0" group="1" density="0" rgba="0.752941 0.752941 0.752941 1" mesh="L_thumb_proximal_base" />
                            <geom type="mesh" rgba="0.752941 0.752941 0.752941 1" mesh="L_thumb_proximal_base" />
                            <body name="L_thumb_proximal" pos="0.011954 -0.00104968 0" quat="0.999041 0 0 -0.0437786">
                              <inertial pos="0.0236969 0 -0.0146724" quat="0.655148 -0.266048 -0.266048 0.655148" mass="0.0615843" diaginertia="2.013e-05 1.73022e-05 5.79777e-06" />
                              <joint name="L_thumb_MCP_joint2" pos="0 0 0" axis="0 1 0" range="0 0.5" actuatorfrcrange="-1 1" />
                              <geom type="mesh" contype="0" conaffinity="0" group="1" density="0" rgba="0.752941 0.752941 0.752941 1" mesh="L_thumb_proximal" />
                              <geom type="mesh" rgba="0.752941 0.752941 0.752941 1" mesh="L_thumb_proximal" />
                              <body name="L_thumb_intermediate" pos="0.0442886 0 -0.0376633">
                                <inertial pos="0.00973134 0 -0.00266466" quat="0.681637 -0.188072 -0.188072 0.681637" mass="0.0153834" diaginertia="1.72e-06 1.65294e-06 7.67055e-07" />
                                <joint name="L_thumb_PIP_joint" pos="0 0 0" axis="0 1 0" range="0 1" actuatorfrcrange="-1 1" />
                                <geom type="mesh" contype="0" conaffinity="0" group="1" density="0" rgba="0.752941 0.752941 0.752941 1" mesh="L_thumb_intermediate" />
                                <geom type="mesh" rgba="0.752941 0.752941 0.752941 1" mesh="L_thumb_intermediate" />
                                <body name="L_thumb_distal" pos="0.0164679 0 -0.0154615">
                                  <inertial pos="0.00714221 -1.54e-06 -0.00689404" quat="0.967006 0 -0.254755 0" mass="0.0104374" diaginertia="8.73238e-07 8.6e-07 4.06762e-07" />
                                  <joint name="L_thumb_DIP_joint" pos="0 0 0" axis="0 1 0" range="0 1.2" actuatorfrcrange="-1 1" />
                                  <geom type="mesh" contype="0" conaffinity="0" group="1" density="0" rgba="0.752941 0.752941 0.752941 1" mesh="L_thumb_distal" />
                                  <geom type="mesh" rgba="0.752941 0.752941 0.752941 1" mesh="L_thumb_distal" />
                                </body>
                              </body>
                            </body>
                          </body>
                          <body name="L_index_proximal" pos="0.026942 0.0095 -0.114975" quat="0.999657 0 -0.0261769 0">
                            <inertial pos="0 0.00199817 -0.0131171" quat="0.707089 -0.00501356 0.00501356 0.707089" mass="0.0145411" diaginertia="1.95028e-06 1.95e-06 5.39716e-07" />
                            <joint name="L_index_MCP_joint" pos="0 0 0" axis="-1 0 0" range="0 1.7" actuatorfrcrange="-1 1" />
                            <geom type="mesh" contype="0" conaffinity="0" group="1" density="0" rgba="0.752941 0.752941 0.752941 1" mesh="L_index_proximal" />
                            <geom type="mesh" rgba="0.752941 0.752941 0.752941 1" mesh="L_index_proximal" />
                            <body name="L_index_distal" pos="0 -0.00111269 -0.0319806">
                              <inertial pos="0 0.00168954 -0.0153694" quat="0.996466 -0.0839918 0 0" mass="0.00905901" diaginertia="1.73e-06 1.72245e-06 2.07554e-07" />
                              <joint name="L_index_DIP_joint" pos="0 0 0" axis="-1 0 0" range="0 1.6" actuatorfrcrange="-1 1" />
                              <geom type="mesh" contype="0" conaffinity="0" group="1" density="0" rgba="0.752941 0.752941 0.752941 1" mesh="L_index_distal" />
                              <geom type="mesh" rgba="0.752941 0.752941 0.752941 1" mesh="L_index_distal" />
                            </body>
                          </body>
                          <body name="L_middle_proximal" pos="0.008 0.0145 -0.128">
                            <inertial pos="0 0.00115546 -0.0133419" quat="0.999362 -0.0357184 0 0" mass="0.013131" diaginertia="1.94e-06 1.93716e-06 5.32843e-07" />
                            <joint name="L_middle_MCP_joint" pos="0 0 0" axis="-1 0 0" range="0 1.7" actuatorfrcrange="-1 1" />
                            <geom type="mesh" contype="0" conaffinity="0" group="1" density="0" rgba="0.752941 0.752941 0.752941 1" mesh="L_middle_proximal" />
                            <geom type="mesh" rgba="0.752941 0.752941 0.752941 1" mesh="L_middle_proximal" />
                            <body name="L_middle_distal" pos="0 -0.00293735 -0.0318649">
                              <inertial pos="0 -3.933e-05 -0.0154619" quat="0.990386 -0.138332 0 0" mass="0.00905901" diaginertia="1.73e-06 1.72396e-06 2.06037e-07" />
                              <joint name="L_middle_DIP_joint" pos="0 0 0" axis="-1 0 0" range="0 1.6" actuatorfrcrange="-1 1" />
                              <geom type="mesh" contype="0" conaffinity="0" group="1" density="0" rgba="0.752941 0.752941 0.752941 1" mesh="L_middle_distal" />
                              <geom type="mesh" rgba="0.752941 0.752941 0.752941 1" mesh="L_middle_distal" />
                            </body>
                          </body>
                          <body name="L_ring_proximal" pos="-0.010942 0.0095 -0.119975" quat="0.999657 0 0.0261769 0">
                            <inertial pos="-3.95e-06 0.00199338 -0.0131311" quat="0.707089 -0.00501356 0.00501356 0.707089" mass="0.0145411" diaginertia="1.95028e-06 1.95e-06 5.39716e-07" />
                            <joint name="L_ring_MCP_joint" pos="0 0 0" axis="-1 0 0" range="0 1.7" actuatorfrcrange="-1 1" />
                            <geom type="mesh" contype="0" conaffinity="0" group="1" density="0" rgba="0.752941 0.752941 0.752941 1" mesh="L_ring_proximal" />
                            <geom type="mesh" rgba="0.752941 0.752941 0.752941 1" mesh="L_ring_proximal" />
                            <body name="L_ring_distal" pos="0 -0.00111269 -0.0319806">
                              <inertial pos="0 0.00168954 -0.0153694" quat="0.996466 -0.0839918 0 0" mass="0.00905901" diaginertia="1.73e-06 1.72245e-06 2.07554e-07" />
                              <joint name="L_ring_DIP_joint" pos="0 0 0" axis="-1 0 0" range="0 1.6" actuatorfrcrange="-1 1" />
                              <geom type="mesh" contype="0" conaffinity="0" group="1" density="0" rgba="0.752941 0.752941 0.752941 1" mesh="L_ring_distal" />
                              <geom type="mesh" rgba="0.752941 0.752941 0.752941 1" mesh="L_ring_distal" />
                            </body>
                          </body>
                          <body name="L_pinky_proximal" pos="-0.0301936 0.0045 -0.112866" quat="0.998135 0 0.0610485 0">
                            <inertial pos="0 0.00191043 -0.0132257" quat="0.707089 -0.00501356 0.00501356 0.707089" mass="0.013131" diaginertia="1.94028e-06 1.94e-06 5.29716e-07" />
                            <joint name="L_pinky_MCP_joint" pos="0 0 0" axis="-1 0 0" range="0 1.7" actuatorfrcrange="-1 1" />
                            <geom type="mesh" contype="0" conaffinity="0" group="1" density="0" rgba="0.752941 0.752941 0.752941 1" mesh="L_pinky_proximal" />
                            <geom type="mesh" rgba="0.752941 0.752941 0.752941 1" mesh="L_pinky_proximal" />
                            <body name="L_pinky_distal" pos="0 -0.00111269 -0.0319806">
                              <inertial pos="1.99e-06 0.00260409 -0.0109991" quat="0.997444 -0.0714519 0 0" mass="0.00693901" diaginertia="8.6e-07 8.54401e-07 1.45599e-07" />
                              <joint name="L_pinky_DIP_joint" pos="0 0 0" axis="-1 0 0" range="0 1.6" actuatorfrcrange="-1 1" />
                              <geom type="mesh" contype="0" conaffinity="0" group="1" density="0" rgba="0.752941 0.752941 0.752941 1" mesh="L_pinky_distal" />
                              <geom type="mesh" rgba="0.752941 0.752941 0.752941 1" mesh="L_pinky_distal" />
                            </body>
                          </body>
                        </body>
                      </body>
                    </body>
                  </body>
                </body>
              </body>
            </body>
            <body name="shoulderPitchRight" pos="0 -0.165094 0.25923" quat="0.984808 -0.173648 0 0">
              <inertial pos="0.00536737 -0.0269397 0.00010693" quat="0.0534521 0.70731 -0.0534944 0.702847" mass="0.216487" diaginertia="0.000381338 0.000323123 0.000187559" />
              <joint name="shoulderPitch_Right" pos="0 0 0" axis="0 1 0" range="-3.613 2.042" actuatorfrcrange="-65 65" />
              <geom type="mesh" contype="0" conaffinity="0" group="1" density="0" rgba="1 1 1 1" mesh="shoulderPitchRight" />
              <geom type="mesh" rgba="1 1 1 1" mesh="shoulderPitchRight" />
              <body name="shoulderRollRight" pos="0.0362 -0.0435 0" quat="0.984808 0.173648 0 0">
                <inertial pos="-0.0342995 -0.00987424 -0.0157184" quat="0.935991 -0.254513 0.072526 0.232131" mass="1.08875" diaginertia="0.0017015 0.00168047 0.000675786" />
                <joint name="shoulderRoll_Right" pos="0 0 0" axis="1 0 0" range="-2.793 0.628" actuatorfrcrange="-65 65" />
                <geom type="mesh" contype="0" conaffinity="0" group="1" density="0" rgba="0.752941 0.752941 0.752941 1" mesh="shoulderRollRight" />
                <geom type="mesh" rgba="0.752941 0.752941 0.752941 1" mesh="shoulderRollRight" />
                <body name="shoulderYawRight" pos="-0.0362 -0.034 -0.0797">
                  <inertial pos="-0.00051403 0.00046316 -0.0619299" quat="0.999904 0.00944783 0.00878884 -0.00513002" mass="0.901393" diaginertia="0.00328611 0.00317291 0.000574074" />
                  <joint name="shoulderYaw_Right" pos="0 0 0" axis="0 0 1" range="-2.583 2.583" actuatorfrcrange="-65 65" />
                  <geom type="mesh" contype="0" conaffinity="0" group="1" density="0" rgba="1 1 1 1" mesh="shoulderYawRight" />
                  <geom type="mesh" rgba="1 1 1 1" mesh="shoulderYawRight" />
                  <body name="elbowRight" pos="0 0.0285 -0.18295">
                    <inertial pos="-0.0140891 -0.0292958 -0.0253475" quat="0.638945 0.191038 0.141578 0.73158" mass="0.917707" diaginertia="0.00110466 0.00109851 0.000457521" />
                    <joint name="elbow_Right" pos="0 0 0" axis="0 1 0" range="-2.496 0.209" actuatorfrcrange="-30 30" />
                    <geom type="mesh" contype="0" conaffinity="0" group="1" density="0" rgba="0.752941 0.752941 0.752941 1" mesh="elbowRight" />
                    <geom type="mesh" rgba="0.752941 0.752941 0.752941 1" mesh="elbowRight" />
                    <body name="wristYawRight" pos="-0.025 -0.0285 -0.0729">
                      <inertial pos="-0.00173086 -0.00013146 -0.0921689" quat="0.999713 -0.00473049 0.00793689 -0.0221096" mass="0.955878" diaginertia="0.00254068 0.00248454 0.000525567" />
                      <joint name="wristYaw_Right" pos="0 0 0" axis="0 0 1" range="-2.67 2.67" actuatorfrcrange="-6.4 6.4" />
                      <geom type="mesh" contype="0" conaffinity="0" group="1" density="0" rgba="0.752941 0.752941 0.752941 1" mesh="wristYawRight" />
                      <geom type="mesh" rgba="0.752941 0.752941 0.752941 1" mesh="wristYawRight" />
                      <body name="wristPitchRight" pos="0 0 -0.2017">
                        <inertial pos="-0.0001758 0.00166098 -2.773e-05" quat="0.501712 0.498275 -0.499779 0.500227" mass="0.119635" diaginertia="3.97702e-05 3.35901e-05 2.68997e-05" />
                        <joint name="wristPitch_Right" pos="0 0 0" axis="0 1 0" range="-0.96 0.96" actuatorfrcrange="-6.4 6.4" />
                        <geom type="mesh" contype="0" conaffinity="0" group="1" density="0" rgba="1 1 1 1" mesh="wristPitchRight" />
                        <geom type="mesh" rgba="1 1 1 1" mesh="wristPitchRight" />
                        <body name="wristRollRight">
                          <inertial pos="-0.00030616 -0.00861825 -0.0663443" quat="0.740461 -0.0461653 0.0146289 0.670353" mass="0.358155" diaginertia="0.000433051 0.000319851 0.000182898" />
                          <joint name="wristRoll_Right" pos="0 0 0" axis="1 0 0" range="-0.96 0.96" actuatorfrcrange="-6.4 6.4" />
                          <geom type="mesh" contype="0" conaffinity="0" group="1" density="0" rgba="0.752941 0.752941 0.752941 1" mesh="wristRollRight" />
                          <geom type="mesh" rgba="0.752941 0.752941 0.752941 1" mesh="wristRollRight" />
                          <body name="R_thumb_proximal_base" pos="0.0245 0.01 -0.047">
                            <inertial pos="0.00431634 -0.00026726 -0.00141884" quat="0.373486 0.456556 0.663922 0.459644" mass="0.0089319" diaginertia="5.7482e-07 4.78268e-07 2.66913e-07" />
                            <joint name="R_thumb_MCP_joint1" pos="0 0 0" axis="0 0 1" range="0 1.1" actuatorfrcrange="-1 1" />
                            <geom type="mesh" contype="0" conaffinity="0" group="1" density="0" rgba="0.752941 0.752941 0.752941 1" mesh="R_thumb_proximal_base" />
                            <geom type="mesh" rgba="0.752941 0.752941 0.752941 1" mesh="R_thumb_proximal_base" />
                            <body name="R_thumb_proximal" pos="0.011954 0.00104968 0" quat="0.999041 0 0 0.0437786">
                              <inertial pos="0.0236968 0 -0.0146723" quat="0.655148 -0.266048 -0.266048 0.655148" mass="0.0615843" diaginertia="2.013e-05 1.73022e-05 5.79777e-06" />
                              <joint name="R_thumb_MCP_joint2" pos="0 0 0" axis="0 1 0" range="0 0.5" actuatorfrcrange="-1 1" />
                              <geom type="mesh" contype="0" conaffinity="0" group="1" density="0" rgba="0.752941 0.752941 0.752941 1" mesh="R_thumb_proximal" />
                              <geom type="mesh" rgba="0.752941 0.752941 0.752941 1" mesh="R_thumb_proximal" />
                              <body name="R_thumb_intermediate" pos="0.0442886 0 -0.0376633">
                                <inertial pos="0.00973134 0 -0.00266467" quat="0.681637 -0.188072 -0.188072 0.681637" mass="0.0153834" diaginertia="1.72e-06 1.65294e-06 7.67055e-07" />
                                <joint name="R_thumb_PIP_joint" pos="0 0 0" axis="0 1 0" range="0 1" actuatorfrcrange="-1 1" />
                                <geom type="mesh" contype="0" conaffinity="0" group="1" density="0" rgba="0.752941 0.752941 0.752941 1" mesh="R_thumb_intermediate" />
                                <geom type="mesh" rgba="0.752941 0.752941 0.752941 1" mesh="R_thumb_intermediate" />
                                <body name="R_thumb_distal" pos="0.0164679 0 -0.0154615">
                                  <inertial pos="0.00714151 1.39e-06 -0.00689413" quat="0.967006 0 -0.254755 0" mass="0.0104374" diaginertia="8.73238e-07 8.6e-07 4.06762e-07" />
                                  <joint name="R_thumb_DIP_joint" pos="0 0 0" axis="0 1 0" range="0 1.2" actuatorfrcrange="-1 1" />
                                  <geom type="mesh" contype="0" conaffinity="0" group="1" density="0" rgba="0.752941 0.752941 0.752941 1" mesh="R_thumb_distal" />
                                  <geom type="mesh" rgba="0.752941 0.752941 0.752941 1" mesh="R_thumb_distal" />
                                </body>
                              </body>
                            </body>
                          </body>
                          <body name="R_index_proximal" pos="0.026942 -0.0095 -0.114975" quat="0.999657 0 -0.0261769 0">
                            <inertial pos="0 -0.0019982 -0.0131171" quat="0.707089 0.00501356 -0.00501356 0.707089" mass="0.0145412" diaginertia="1.95028e-06 1.95e-06 5.39716e-07" />
                            <joint name="R_index_MCP_joint" pos="0 0 0" axis="1 0 0" range="0 1.7" actuatorfrcrange="-1 1" />
                            <geom type="mesh" contype="0" conaffinity="0" group="1" density="0" rgba="0.752941 0.752941 0.752941 1" mesh="R_index_proximal" />
                            <geom type="mesh" rgba="0.752941 0.752941 0.752941 1" mesh="R_index_proximal" />
                            <body name="R_index_distal" pos="0 0.00111269 -0.0319806">
                              <inertial pos="0 -0.00168936 -0.0153697" quat="0.996466 0.0839918 0 0" mass="0.00905901" diaginertia="1.73e-06 1.72245e-06 2.07554e-07" />
                              <joint name="R_index_DIP_joint" pos="0 0 0" axis="1 0 0" range="0 1.6" actuatorfrcrange="-1 1" />
                              <geom type="mesh" contype="0" conaffinity="0" group="1" density="0" rgba="0.752941 0.752941 0.752941 1" mesh="R_index_distal" />
                              <geom type="mesh" rgba="0.752941 0.752941 0.752941 1" mesh="R_index_distal" />
                            </body>
                          </body>
                          <body name="R_middle_proximal" pos="0.008 -0.0145 -0.128">
                            <inertial pos="0 -0.00115549 -0.0133419" quat="0.999362 0.0357184 0 0" mass="0.0131311" diaginertia="1.94e-06 1.93716e-06 5.32843e-07" />
                            <joint name="R_middle_MCP_joint" pos="0 0 0" axis="1 0 0" range="0 1.7" actuatorfrcrange="-1 1" />
                            <geom type="mesh" contype="0" conaffinity="0" group="1" density="0" rgba="0.752941 0.752941 0.752941 1" mesh="R_middle_proximal" />
                            <geom type="mesh" rgba="0.752941 0.752941 0.752941 1" mesh="R_middle_proximal" />
                            <body name="R_middle_distal" pos="0 0.00293735 -0.0318649">
                              <inertial pos="0 3.955e-05 -0.0154622" quat="0.990386 0.138332 0 0" mass="0.00905901" diaginertia="1.73e-06 1.72396e-06 2.06037e-07" />
                              <joint name="R_middle_DIP_joint" pos="0 0 0" axis="1 0 0" range="0 1.6" actuatorfrcrange="-1 1" />
                              <geom type="mesh" contype="0" conaffinity="0" group="1" density="0" rgba="0.752941 0.752941 0.752941 1" mesh="R_middle_distal" />
                              <geom type="mesh" rgba="0.752941 0.752941 0.752941 1" mesh="R_middle_distal" />
                            </body>
                          </body>
                          <body name="R_ring_proximal" pos="-0.010942 -0.0095 -0.119975" quat="0.999657 0 0.0261769 0">
                            <inertial pos="0 -0.0019982 -0.0131171" quat="0.707089 0.00501356 -0.00501356 0.707089" mass="0.0145412" diaginertia="1.95028e-06 1.95e-06 5.39716e-07" />
                            <joint name="R_ring_MCP_joint" pos="0 0 0" axis="1 0 0" range="0 1.7" actuatorfrcrange="-1 1" />
                            <geom type="mesh" contype="0" conaffinity="0" group="1" density="0" rgba="0.752941 0.752941 0.752941 1" mesh="R_ring_proximal" />
                            <geom type="mesh" rgba="0.752941 0.752941 0.752941 1" mesh="R_ring_proximal" />
                            <body name="R_ring_distal" pos="0 0.00111269 -0.0319806">
                              <inertial pos="0 -0.00168936 -0.0153697" quat="0.996466 0.0839918 0 0" mass="0.00905901" diaginertia="1.73e-06 1.72245e-06 2.07554e-07" />
                              <joint name="R_ring_DIP_joint" pos="0 0 0" axis="1 0 0" range="0 1.6" actuatorfrcrange="-1 1" />
                              <geom type="mesh" contype="0" conaffinity="0" group="1" density="0" rgba="0.752941 0.752941 0.752941 1" mesh="R_ring_distal" />
                              <geom type="mesh" rgba="0.752941 0.752941 0.752941 1" mesh="R_ring_distal" />
                            </body>
                          </body>
                          <body name="R_pinky_proximal" pos="-0.0301936 -0.0045 -0.112866" quat="0.998135 0 0.0610485 0">
                            <inertial pos="0 -0.00191046 -0.0132258" quat="0.707089 0.00501356 -0.00501356 0.707089" mass="0.0131311" diaginertia="1.94028e-06 1.94e-06 5.29716e-07" />
                            <joint name="R_pinky_MCP_joint" pos="0 0 0" axis="1 0 0" range="0 1.7" actuatorfrcrange="-1 1" />
                            <geom type="mesh" contype="0" conaffinity="0" group="1" density="0" rgba="0.752941 0.752941 0.752941 1" mesh="R_pinky_proximal" />
                            <geom type="mesh" rgba="0.752941 0.752941 0.752941 1" mesh="R_pinky_proximal" />
                            <body name="R_pinky_distal" pos="0 0.00111269 -0.0319806">
                              <inertial pos="2.01e-06 -0.00260417 -0.0109989" quat="0.997444 0.0714519 0 0" mass="0.00693901" diaginertia="8.6e-07 8.54401e-07 1.45599e-07" />
                              <joint name="R_pinky_DIP_joint" pos="0 0 0" axis="1 0 0" range="0 1.6" actuatorfrcrange="-1 1" />
                              <geom type="mesh" contype="0" conaffinity="0" group="1" density="0" rgba="0.752941 0.752941 0.752941 1" mesh="R_pinky_distal" />
                              <geom type="mesh" rgba="0.752941 0.752941 0.752941 1" mesh="R_pinky_distal" />
                            </body>
                          </body>
                        </body>
                      </body>
                    </body>
                  </body>
                </body>
              </body>
            </body>
            <body name="neckYaw_link" pos="-0.013 0 0.29855">
              <inertial pos="0.0228442 -0.00120876 0.0992634" quat="0.719761 0.0861591 0.0813325 0.684036" mass="0.399168" diaginertia="0.00132274 0.00131438 0.000128684" />
              <joint name="neckYaw" pos="0 0 0" axis="0 0 1" range="-1.571 1.571" actuatorfrcrange="-6.4 6.4" />
              <geom type="mesh" contype="0" conaffinity="0" group="1" density="0" rgba="0.752941 0.752941 0.752941 1" mesh="neckYaw_link" />
              <geom type="mesh" rgba="0.752941 0.752941 0.752941 1" mesh="neckYaw_link" />
              <body name="neckPitch_link" pos="0.0316 0.01995 0.14595">
                <inertial pos="0.0174597 -0.0210407 0.0470534" quat="0.0369738 0.852876 0.0341259 0.519683" mass="0.956204" diaginertia="0.00368991 0.00348806 0.00231156" />
                <joint name="neckPitch" pos="0 0 0" axis="0 1 0" range="-0.873 0.873" actuatorfrcrange="-6.4 6.4" />
                <geom type="mesh" contype="0" conaffinity="0" group="1" density="0" rgba="0.752941 0.752941 0.752941 1" mesh="neckPitch_link" />
                <geom type="mesh" rgba="0.752941 0.752941 0.752941 1" mesh="neckPitch_link" />
              </body>
            </body>
          </body>
        </body>
      </body>
      <site name="imu" pos="0 0 0" />
    </body>
  </worldbody>
  <actuator>
    <motor joint="hipPitch_Left" name="hipPitch_Left" ctrlrange="-230.0 230.0" />
    <motor joint="hipRoll_Left" name="hipRoll_Left" ctrlrange="-160.0 160.0" />
    <motor joint="hipYaw_Left" name="hipYaw_Left" ctrlrange="-105.0 105.0" />
    <motor joint="kneePitch_Left" name="kneePitch_Left" ctrlrange="-230.0 230.0" />
    <motor joint="anklePitch_Left" name="anklePitch_Left" ctrlrange="-40.0 40.0" />
    <motor joint="ankleRoll_Left" name="ankleRoll_Left" ctrlrange="-12.0 12.0" />
    <motor joint="hipPitch_Right" name="hipPitch_Right" ctrlrange="-230.0 230.0" />
    <motor joint="hipRoll_Right" name="hipRoll_Right" ctrlrange="-160.0 160.0" />
    <motor joint="hipYaw_Right" name="hipYaw_Right" ctrlrange="-105.0 105.0" />
    <motor joint="kneePitch_Right" name="kneePitch_Right" ctrlrange="-230.0 230.0" />
    <motor joint="anklePitch_Right" name="anklePitch_Right" ctrlrange="-40.0 40.0" />
    <motor joint="ankleRoll_Right" name="ankleRoll_Right" ctrlrange="-12.0 12.0" />
    <motor joint="waistRoll" name="waistRoll" ctrlrange="-110.0 110.0" />
    <motor joint="waistPitch" name="waistPitch" ctrlrange="-110.0 110.0" />
    <motor joint="waistYaw" name="waistYaw" ctrlrange="-110.0 110.0" />
    <motor joint="shoulderPitch_Left" name="shoulderPitch_Left" ctrlrange="-65.0 65.0" />
    <motor joint="shoulderRoll_Left" name="shoulderRoll_Left" ctrlrange="-65.0 65.0" />
    <motor joint="shoulderYaw_Left" name="shoulderYaw_Left" ctrlrange="-65.0 65.0" />
    <motor joint="elbow_Left" name="elbow_Left" ctrlrange="-30.0 30.0" />
    <motor joint="wristYaw_Left" name="wristYaw_Left" ctrlrange="-6.4 6.4" />
    <motor joint="wristPitch_Left" name="wristPitch_Left" ctrlrange="-6.4 6.4" />
    <motor joint="wristRoll_Left" name="wristRoll_Left" ctrlrange="-6.4 6.4" />
    <motor joint="L_thumb_MCP_joint1" name="L_thumb_MCP_joint1" ctrlrange="-1.0 1.0" />
    <motor joint="L_thumb_MCP_joint2" name="L_thumb_MCP_joint2" ctrlrange="-1.0 1.0" />
    <motor joint="L_thumb_PIP_joint" name="L_thumb_PIP_joint" ctrlrange="-1.0 1.0" />
    <motor joint="L_thumb_DIP_joint" name="L_thumb_DIP_joint" ctrlrange="-1.0 1.0" />
    <motor joint="L_index_MCP_joint" name="L_index_MCP_joint" ctrlrange="-1.0 1.0" />
    <motor joint="L_index_DIP_joint" name="L_index_DIP_joint" ctrlrange="-1.0 1.0" />
    <motor joint="L_middle_MCP_joint" name="L_middle_MCP_joint" ctrlrange="-1.0 1.0" />
    <motor joint="L_middle_DIP_joint" name="L_middle_DIP_joint" ctrlrange="-1.0 1.0" />
    <motor joint="L_ring_MCP_joint" name="L_ring_MCP_joint" ctrlrange="-1.0 1.0" />
    <motor joint="L_ring_DIP_joint" name="L_ring_DIP_joint" ctrlrange="-1.0 1.0" />
    <motor joint="L_pinky_MCP_joint" name="L_pinky_MCP_joint" ctrlrange="-1.0 1.0" />
    <motor joint="L_pinky_DIP_joint" name="L_pinky_DIP_joint" ctrlrange="-1.0 1.0" />
    <motor joint="shoulderPitch_Right" name="shoulderPitch_Right" ctrlrange="-65.0 65.0" />
    <motor joint="shoulderRoll_Right" name="shoulderRoll_Right" ctrlrange="-65.0 65.0" />
    <motor joint="shoulderYaw_Right" name="shoulderYaw_Right" ctrlrange="-65.0 65.0" />
    <motor joint="elbow_Right" name="elbow_Right" ctrlrange="-30.0 30.0" />
    <motor joint="wristYaw_Right" name="wristYaw_Right" ctrlrange="-6.4 6.4" />
    <motor joint="wristPitch_Right" name="wristPitch_Right" ctrlrange="-6.4 6.4" />
    <motor joint="wristRoll_Right" name="wristRoll_Right" ctrlrange="-6.4 6.4" />
    <motor joint="R_thumb_MCP_joint1" name="R_thumb_MCP_joint1" ctrlrange="-1.0 1.0" />
    <motor joint="R_thumb_MCP_joint2" name="R_thumb_MCP_joint2" ctrlrange="-1.0 1.0" />
    <motor joint="R_thumb_PIP_joint" name="R_thumb_PIP_joint" ctrlrange="-1.0 1.0" />
    <motor joint="R_thumb_DIP_joint" name="R_thumb_DIP_joint" ctrlrange="-1.0 1.0" />
    <motor joint="R_index_MCP_joint" name="R_index_MCP_joint" ctrlrange="-1.0 1.0" />
    <motor joint="R_index_DIP_joint" name="R_index_DIP_joint" ctrlrange="-1.0 1.0" />
    <motor joint="R_middle_MCP_joint" name="R_middle_MCP_joint" ctrlrange="-1.0 1.0" />
    <motor joint="R_middle_DIP_joint" name="R_middle_DIP_joint" ctrlrange="-1.0 1.0" />
    <motor joint="R_ring_MCP_joint" name="R_ring_MCP_joint" ctrlrange="-1.0 1.0" />
    <motor joint="R_ring_DIP_joint" name="R_ring_DIP_joint" ctrlrange="-1.0 1.0" />
    <motor joint="R_pinky_MCP_joint" name="R_pinky_MCP_joint" ctrlrange="-1.0 1.0" />
    <motor joint="R_pinky_DIP_joint" name="R_pinky_DIP_joint" ctrlrange="-1.0 1.0" />
    <motor joint="neckYaw" name="neckYaw" ctrlrange="-6.4 6.4" />
    <motor joint="neckPitch" name="neckPitch" ctrlrange="-6.4 6.4" />
  </actuator>
  <sensor>
    <jointpos name="pos_hipPitch_Left" joint="hipPitch_Left" />
    <jointpos name="pos_hipRoll_Left" joint="hipRoll_Left" />
    <jointpos name="pos_hipYaw_Left" joint="hipYaw_Left" />
    <jointpos name="pos_kneePitch_Left" joint="kneePitch_Left" />
    <jointpos name="pos_anklePitch_Left" joint="anklePitch_Left" />
    <jointpos name="pos_ankleRoll_Left" joint="ankleRoll_Left" />
    <jointpos name="pos_hipPitch_Right" joint="hipPitch_Right" />
    <jointpos name="pos_hipRoll_Right" joint="hipRoll_Right" />
    <jointpos name="pos_hipYaw_Right" joint="hipYaw_Right" />
    <jointpos name="pos_kneePitch_Right" joint="kneePitch_Right" />
    <jointpos name="pos_anklePitch_Right" joint="anklePitch_Right" />
    <jointpos name="pos_ankleRoll_Right" joint="ankleRoll_Right" />
    <jointpos name="pos_waistRoll" joint="waistRoll" />
    <jointpos name="pos_waistPitch" joint="waistPitch" />
    <jointpos name="pos_waistYaw" joint="waistYaw" />
    <jointpos name="pos_shoulderPitch_Left" joint="shoulderPitch_Left" />
    <jointpos name="pos_shoulderRoll_Left" joint="shoulderRoll_Left" />
    <jointpos name="pos_shoulderYaw_Left" joint="shoulderYaw_Left" />
    <jointpos name="pos_elbow_Left" joint="elbow_Left" />
    <jointpos name="pos_wristYaw_Left" joint="wristYaw_Left" />
    <jointpos name="pos_wristPitch_Left" joint="wristPitch_Left" />
    <jointpos name="pos_wristRoll_Left" joint="wristRoll_Left" />
    <jointpos name="pos_L_thumb_MCP_joint1" joint="L_thumb_MCP_joint1" />
    <jointpos name="pos_L_thumb_MCP_joint2" joint="L_thumb_MCP_joint2" />
    <jointpos name="pos_L_thumb_PIP_joint" joint="L_thumb_PIP_joint" />
    <jointpos name="pos_L_thumb_DIP_joint" joint="L_thumb_DIP_joint" />
    <jointpos name="pos_L_index_MCP_joint" joint="L_index_MCP_joint" />
    <jointpos name="pos_L_index_DIP_joint" joint="L_index_DIP_joint" />
    <jointpos name="pos_L_middle_MCP_joint" joint="L_middle_MCP_joint" />
    <jointpos name="pos_L_middle_DIP_joint" joint="L_middle_DIP_joint" />
    <jointpos name="pos_L_ring_MCP_joint" joint="L_ring_MCP_joint" />
    <jointpos name="pos_L_ring_DIP_joint" joint="L_ring_DIP_joint" />
    <jointpos name="pos_L_pinky_MCP_joint" joint="L_pinky_MCP_joint" />
    <jointpos name="pos_L_pinky_DIP_joint" joint="L_pinky_DIP_joint" />
    <jointpos name="pos_shoulderPitch_Right" joint="shoulderPitch_Right" />
    <jointpos name="pos_shoulderRoll_Right" joint="shoulderRoll_Right" />
    <jointpos name="pos_shoulderYaw_Right" joint="shoulderYaw_Right" />
    <jointpos name="pos_elbow_Right" joint="elbow_Right" />
    <jointpos name="pos_wristYaw_Right" joint="wristYaw_Right" />
    <jointpos name="pos_wristPitch_Right" joint="wristPitch_Right" />
    <jointpos name="pos_wristRoll_Right" joint="wristRoll_Right" />
    <jointpos name="pos_R_thumb_MCP_joint1" joint="R_thumb_MCP_joint1" />
    <jointpos name="pos_R_thumb_MCP_joint2" joint="R_thumb_MCP_joint2" />
    <jointpos name="pos_R_thumb_PIP_joint" joint="R_thumb_PIP_joint" />
    <jointpos name="pos_R_thumb_DIP_joint" joint="R_thumb_DIP_joint" />
    <jointpos name="pos_R_index_MCP_joint" joint="R_index_MCP_joint" />
    <jointpos name="pos_R_index_DIP_joint" joint="R_index_DIP_joint" />
    <jointpos name="pos_R_middle_MCP_joint" joint="R_middle_MCP_joint" />
    <jointpos name="pos_R_middle_DIP_joint" joint="R_middle_DIP_joint" />
    <jointpos name="pos_R_ring_MCP_joint" joint="R_ring_MCP_joint" />
    <jointpos name="pos_R_ring_DIP_joint" joint="R_ring_DIP_joint" />
    <jointpos name="pos_R_pinky_MCP_joint" joint="R_pinky_MCP_joint" />
    <jointpos name="pos_R_pinky_DIP_joint" joint="R_pinky_DIP_joint" />
    <jointpos name="pos_neckYaw" joint="neckYaw" />
    <jointpos name="pos_neckPitch" joint="neckPitch" />
    <jointvel name="vel_hipPitch_Left" joint="hipPitch_Left" />
    <jointvel name="vel_hipRoll_Left" joint="hipRoll_Left" />
    <jointvel name="vel_hipYaw_Left" joint="hipYaw_Left" />
    <jointvel name="vel_kneePitch_Left" joint="kneePitch_Left" />
    <jointvel name="vel_anklePitch_Left" joint="anklePitch_Left" />
    <jointvel name="vel_ankleRoll_Left" joint="ankleRoll_Left" />
    <jointvel name="vel_hipPitch_Right" joint="hipPitch_Right" />
    <jointvel name="vel_hipRoll_Right" joint="hipRoll_Right" />
    <jointvel name="vel_hipYaw_Right" joint="hipYaw_Right" />
    <jointvel name="vel_kneePitch_Right" joint="kneePitch_Right" />
    <jointvel name="vel_anklePitch_Right" joint="anklePitch_Right" />
    <jointvel name="vel_ankleRoll_Right" joint="ankleRoll_Right" />
    <jointvel name="vel_waistRoll" joint="waistRoll" />
    <jointvel name="vel_waistPitch" joint="waistPitch" />
    <jointvel name="vel_waistYaw" joint="waistYaw" />
    <jointvel name="vel_shoulderPitch_Left" joint="shoulderPitch_Left" />
    <jointvel name="vel_shoulderRoll_Left" joint="shoulderRoll_Left" />
    <jointvel name="vel_shoulderYaw_Left" joint="shoulderYaw_Left" />
    <jointvel name="vel_elbow_Left" joint="elbow_Left" />
    <jointvel name="vel_wristYaw_Left" joint="wristYaw_Left" />
    <jointvel name="vel_wristPitch_Left" joint="wristPitch_Left" />
    <jointvel name="vel_wristRoll_Left" joint="wristRoll_Left" />
    <jointvel name="vel_L_thumb_MCP_joint1" joint="L_thumb_MCP_joint1" />
    <jointvel name="vel_L_thumb_MCP_joint2" joint="L_thumb_MCP_joint2" />
    <jointvel name="vel_L_thumb_PIP_joint" joint="L_thumb_PIP_joint" />
    <jointvel name="vel_L_thumb_DIP_joint" joint="L_thumb_DIP_joint" />
    <jointvel name="vel_L_index_MCP_joint" joint="L_index_MCP_joint" />
    <jointvel name="vel_L_index_DIP_joint" joint="L_index_DIP_joint" />
    <jointvel name="vel_L_middle_MCP_joint" joint="L_middle_MCP_joint" />
    <jointvel name="vel_L_middle_DIP_joint" joint="L_middle_DIP_joint" />
    <jointvel name="vel_L_ring_MCP_joint" joint="L_ring_MCP_joint" />
    <jointvel name="vel_L_ring_DIP_joint" joint="L_ring_DIP_joint" />
    <jointvel name="vel_L_pinky_MCP_joint" joint="L_pinky_MCP_joint" />
    <jointvel name="vel_L_pinky_DIP_joint" joint="L_pinky_DIP_joint" />
    <jointvel name="vel_shoulderPitch_Right" joint="shoulderPitch_Right" />
    <jointvel name="vel_shoulderRoll_Right" joint="shoulderRoll_Right" />
    <jointvel name="vel_shoulderYaw_Right" joint="shoulderYaw_Right" />
    <jointvel name="vel_elbow_Right" joint="elbow_Right" />
    <jointvel name="vel_wristYaw_Right" joint="wristYaw_Right" />
    <jointvel name="vel_wristPitch_Right" joint="wristPitch_Right" />
    <jointvel name="vel_wristRoll_Right" joint="wristRoll_Right" />
    <jointvel name="vel_R_thumb_MCP_joint1" joint="R_thumb_MCP_joint1" />
    <jointvel name="vel_R_thumb_MCP_joint2" joint="R_thumb_MCP_joint2" />
    <jointvel name="vel_R_thumb_PIP_joint" joint="R_thumb_PIP_joint" />
    <jointvel name="vel_R_thumb_DIP_joint" joint="R_thumb_DIP_joint" />
    <jointvel name="vel_R_index_MCP_joint" joint="R_index_MCP_joint" />
    <jointvel name="vel_R_index_DIP_joint" joint="R_index_DIP_joint" />
    <jointvel name="vel_R_middle_MCP_joint" joint="R_middle_MCP_joint" />
    <jointvel name="vel_R_middle_DIP_joint" joint="R_middle_DIP_joint" />
    <jointvel name="vel_R_ring_MCP_joint" joint="R_ring_MCP_joint" />
    <jointvel name="vel_R_ring_DIP_joint" joint="R_ring_DIP_joint" />
    <jointvel name="vel_R_pinky_MCP_joint" joint="R_pinky_MCP_joint" />
    <jointvel name="vel_R_pinky_DIP_joint" joint="R_pinky_DIP_joint" />
    <jointvel name="vel_neckYaw" joint="neckYaw" />
    <jointvel name="vel_neckPitch" joint="neckPitch" />
    <jointactuatorfrc name="force_hipPitch_Left" joint="hipPitch_Left" />
    <jointactuatorfrc name="force_hipRoll_Left" joint="hipRoll_Left" />
    <jointactuatorfrc name="force_hipYaw_Left" joint="hipYaw_Left" />
    <jointactuatorfrc name="force_kneePitch_Left" joint="kneePitch_Left" />
    <jointactuatorfrc name="force_anklePitch_Left" joint="anklePitch_Left" />
    <jointactuatorfrc name="force_ankleRoll_Left" joint="ankleRoll_Left" />
    <jointactuatorfrc name="force_hipPitch_Right" joint="hipPitch_Right" />
    <jointactuatorfrc name="force_hipRoll_Right" joint="hipRoll_Right" />
    <jointactuatorfrc name="force_hipYaw_Right" joint="hipYaw_Right" />
    <jointactuatorfrc name="force_kneePitch_Right" joint="kneePitch_Right" />
    <jointactuatorfrc name="force_anklePitch_Right" joint="anklePitch_Right" />
    <jointactuatorfrc name="force_ankleRoll_Right" joint="ankleRoll_Right" />
    <jointactuatorfrc name="force_waistRoll" joint="waistRoll" />
    <jointactuatorfrc name="force_waistPitch" joint="waistPitch" />
    <jointactuatorfrc name="force_waistYaw" joint="waistYaw" />
    <jointactuatorfrc name="force_shoulderPitch_Left" joint="shoulderPitch_Left" />
    <jointactuatorfrc name="force_shoulderRoll_Left" joint="shoulderRoll_Left" />
    <jointactuatorfrc name="force_shoulderYaw_Left" joint="shoulderYaw_Left" />
    <jointactuatorfrc name="force_elbow_Left" joint="elbow_Left" />
    <jointactuatorfrc name="force_wristYaw_Left" joint="wristYaw_Left" />
    <jointactuatorfrc name="force_wristPitch_Left" joint="wristPitch_Left" />
    <jointactuatorfrc name="force_wristRoll_Left" joint="wristRoll_Left" />
    <jointactuatorfrc name="force_L_thumb_MCP_joint1" joint="L_thumb_MCP_joint1" />
    <jointactuatorfrc name="force_L_thumb_MCP_joint2" joint="L_thumb_MCP_joint2" />
    <jointactuatorfrc name="force_L_thumb_PIP_joint" joint="L_thumb_PIP_joint" />
    <jointactuatorfrc name="force_L_thumb_DIP_joint" joint="L_thumb_DIP_joint" />
    <jointactuatorfrc name="force_L_index_MCP_joint" joint="L_index_MCP_joint" />
    <jointactuatorfrc name="force_L_index_DIP_joint" joint="L_index_DIP_joint" />
    <jointactuatorfrc name="force_L_middle_MCP_joint" joint="L_middle_MCP_joint" />
    <jointactuatorfrc name="force_L_middle_DIP_joint" joint="L_middle_DIP_joint" />
    <jointactuatorfrc name="force_L_ring_MCP_joint" joint="L_ring_MCP_joint" />
    <jointactuatorfrc name="force_L_ring_DIP_joint" joint="L_ring_DIP_joint" />
    <jointactuatorfrc name="force_L_pinky_MCP_joint" joint="L_pinky_MCP_joint" />
    <jointactuatorfrc name="force_L_pinky_DIP_joint" joint="L_pinky_DIP_joint" />
    <jointactuatorfrc name="force_shoulderPitch_Right" joint="shoulderPitch_Right" />
    <jointactuatorfrc name="force_shoulderRoll_Right" joint="shoulderRoll_Right" />
    <jointactuatorfrc name="force_shoulderYaw_Right" joint="shoulderYaw_Right" />
    <jointactuatorfrc name="force_elbow_Right" joint="elbow_Right" />
    <jointactuatorfrc name="force_wristYaw_Right" joint="wristYaw_Right" />
    <jointactuatorfrc name="force_wristPitch_Right" joint="wristPitch_Right" />
    <jointactuatorfrc name="force_wristRoll_Right" joint="wristRoll_Right" />
    <jointactuatorfrc name="force_R_thumb_MCP_joint1" joint="R_thumb_MCP_joint1" />
    <jointactuatorfrc name="force_R_thumb_MCP_joint2" joint="R_thumb_MCP_joint2" />
    <jointactuatorfrc name="force_R_thumb_PIP_joint" joint="R_thumb_PIP_joint" />
    <jointactuatorfrc name="force_R_thumb_DIP_joint" joint="R_thumb_DIP_joint" />
    <jointactuatorfrc name="force_R_index_MCP_joint" joint="R_index_MCP_joint" />
    <jointactuatorfrc name="force_R_index_DIP_joint" joint="R_index_DIP_joint" />
    <jointactuatorfrc name="force_R_middle_MCP_joint" joint="R_middle_MCP_joint" />
    <jointactuatorfrc name="force_R_middle_DIP_joint" joint="R_middle_DIP_joint" />
    <jointactuatorfrc name="force_R_ring_MCP_joint" joint="R_ring_MCP_joint" />
    <jointactuatorfrc name="force_R_ring_DIP_joint" joint="R_ring_DIP_joint" />
    <jointactuatorfrc name="force_R_pinky_MCP_joint" joint="R_pinky_MCP_joint" />
    <jointactuatorfrc name="force_R_pinky_DIP_joint" joint="R_pinky_DIP_joint" />
    <jointactuatorfrc name="force_neckYaw" joint="neckYaw" />
    <jointactuatorfrc name="force_neckPitch" joint="neckPitch" />
    <accelerometer name="BodyAcc" site="imu" />
    <gyro name="BodyGyro" site="imu" />
    <framepos name="BodyPos" objtype="site" objname="imu" />
    <framelinvel name="BodyVel" objtype="site" objname="imu" />
    <framequat name="BodyQuat" objtype="site" objname="imu" />
  </sensor>

  <contact>
    <exclude body1="wristYawLeft" body2="wristRollLeft"/>
    <exclude body1="wristRollLeft" body2="L_thumb_proximal"/>
    <exclude body1="wristYawRight" body2="wristRollRight"/>
    <exclude body1="wristRollRight" body2="R_thumb_proximal"/>
  </contact>
</mujoco>