<?xml version='1.0' encoding='utf-8'?>
<robot name="adams_u">
  <link name="lifting_Columns">
    <inertial>
      <origin xyz="9.03635035444037E-05 -3.16722893623993E-05 -0.722724623743625" rpy="0 0 0" />
      <mass value="16.1204633267776" />
      <inertia ixx="0.58293085339089" ixy="8.29673282366126E-06" ixz="-0.000193074913370088"
        iyy="0.351926408749018" iyz="4.40353995991562E-06" izz="0.720002300370631" />
    </inertial>
    <visual>
      <origin xyz="0 0 0" rpy="0 0 0" />
      <geometry>
        <mesh filename="package://adam_description/urdf/adam_u/meshes/lifting_Columns.STL" />
      </geometry>
      <material name="">
        <color rgba="1 1 1 1" />
      </material>
    </visual>
    <collision>
      <origin xyz="0 0 0" rpy="0 0 0" />
      <geometry>
        <mesh filename="package://adam_description/urdf/adam_u/meshes/lifting_Columns.STL" />
      </geometry>
    </collision>
  </link>
  <link name="waistRoll">
    <inertial>
      <origin xyz="0.000547726366994549 0.000547713025957098 0.040000008989702" rpy="0 0 0" />
      <mass value="0.673510726802016" />
      <inertia ixx="0.00152791839150008" ixy="1.0556953734125E-07" ixz="7.53266669398681E-06"
        iyy="0.00152792913088045" iyz="-7.54098911753392E-06" izz="0.000533987490624141" />
    </inertial>
    <visual>
      <origin xyz="0 0 0" rpy="0 0 0" />
      <geometry>
        <mesh filename="package://adam_description/urdf/adam_u/meshes/waistRoll.STL" />
      </geometry>
      <material name="">
        <color rgba="1 1 1 1" />
      </material>
    </visual>
    <collision>
      <origin xyz="0 0 0" rpy="0 0 0" />
      <geometry>
        <mesh filename="package://adam_description/urdf/adam_u/meshes/waistRoll.STL" />
      </geometry>
    </collision>
  </link>
  <joint name="waistRoll" type="revolute">
    <origin xyz="0 0 0.0767" rpy="0 0 0" />
    <parent link="lifting_Columns" />
    <child link="waistRoll" />
    <axis xyz="1 0 0" />
    <limit effort="110" lower="-0.226" upper="0.226" velocity="8.0" />
  </joint>
  <link name="waistPitch">
    <inertial>
      <origin xyz="-0.000746348707936628 0.00427332849629418 0.0224627404160348" rpy="0 0 0" />
      <mass value="0.186307810885884" />
      <inertia ixx="0.000311633701415831" ixy="-9.84948034392484E-08" ixz="1.12476356683969E-06"
        iyy="0.000206855106680981" iyz="1.37216544328579E-05" izz="0.00034504220682227" />
    </inertial>
    <visual>
      <origin xyz="0 0 0" rpy="0 0 0" />
      <geometry>
        <mesh filename="package://adam_description/urdf/adam_u/meshes/waistPitch.STL" />
      </geometry>
      <material name="">
        <color rgba="0.752941176470588 0.752941176470588 0.752941176470588 1" />
      </material>
    </visual>
    <collision>
      <origin xyz="0 0 0" rpy="0 0 0" />
      <geometry>
        <mesh filename="package://adam_description/urdf/adam_u/meshes/waistPitch.STL" />
      </geometry>
    </collision>
  </link>
  <joint name="waistPitch" type="revolute">
    <origin xyz="0 0 0.08" rpy="0 0 0" />
    <parent link="waistRoll" />
    <child link="waistPitch" />
    <axis xyz="0 1 0" />
    <limit effort="110" lower="-0.785" upper="1.308" velocity="8.0" />
  </joint>
  <link name="torso">
    <inertial>
      <origin xyz="0.0101411359435487 9.45822339042846E-06 0.171138320455814" rpy="0 0 0" />
      <mass value="2.71269114410584" />
      <inertia ixx="0.0111572290838724" ixy="-1.34517120444112E-08" ixz="0.000194594724460773"
        iyy="0.00752969495760558" iyz="-2.46742527642332E-06" izz="0.00568939314758386" />
    </inertial>
    <visual>
      <origin xyz="0 0 0" rpy="0 0 0" />
      <geometry>
        <mesh filename="package://adam_description/urdf/adam_u/meshes/torso.STL" />
      </geometry>
      <material name="">
        <color rgba="1 1 1 1" />
      </material>
    </visual>
    <collision>
      <origin xyz="0 0 0" rpy="0 0 0" />
      <geometry>
        <mesh filename="package://adam_description/urdf/adam_u/meshes/torso.STL" />
      </geometry>
    </collision>
  </link>
  <joint name="waistYaw" type="revolute">
    <origin xyz="0 0.0005 0.053" rpy="0 0 0" />
    <parent link="waistPitch" />
    <child link="torso" />
    <axis xyz="0 0 1" />
    <limit effort="110" lower="-0.78" upper="0.78" velocity="8.0" />
  </joint>
  <link name="shoulderPitchLeft">
    <inertial>
      <origin xyz="-0.00143752637481114 0.0268502556245999 0.000108703412754943" rpy="0 0 0" />
      <mass value="0.0738849558917773" />
      <inertia ixx="6.19352546676124E-05" ixy="1.57294591732848E-06" ixz="2.32781171313482E-07"
        iyy="0.000105123142806096" iyz="-1.54930854395079E-07" izz="0.00012503984020453" />
    </inertial>
    <visual>
      <origin xyz="0 0 0" rpy="0 0 0" />
      <geometry>
        <mesh filename="package://adam_description/urdf/adam_u/meshes/shoulderPitchLeft.STL" />
      </geometry>
      <material name="">
        <color rgba="1 1 1 1" />
      </material>
    </visual>
    <collision>
      <origin xyz="0 0 0" rpy="0 0 0" />
      <geometry>
        <mesh filename="package://adam_description/urdf/adam_u/meshes/shoulderPitchLeft.STL" />
      </geometry>
    </collision>
  </link>
  <joint name="shoulderPitch_Left" type="revolute">
    <origin xyz="0 0.16049 0.25755" rpy="0.34907 0 0" />
    <parent link="torso" />
    <child link="shoulderPitchLeft" />
    <axis xyz="0 1 0" />
    <limit effort="65.0" lower="-3.560" upper="1.989" velocity="8.0" />
  </joint>
  <link name="shoulderRollLeft">
    <inertial>
      <origin xyz="-0.0277961115704023 0.0115246226817938 -0.0146354182780329" rpy="0 0 0" />
      <mass value="0.140494630445989" />
      <inertia ixx="0.000177935899487952" ixy="6.78156608511969E-06" ixz="-9.85790273877457E-06"
        iyy="0.000138070726635053" iyz="4.95718682913346E-05" izz="0.000117929645879799" />
    </inertial>
    <visual>
      <origin xyz="0 0 0" rpy="0 0 0" />
      <geometry>
        <mesh filename="package://adam_description/urdf/adam_u/meshes/shoulderRollLeft.STL" />
      </geometry>
      <material name="">
        <color rgba="1 1 1 1" />
      </material>
    </visual>
    <collision>
      <origin xyz="0 0 0" rpy="0 0 0" />
      <geometry>
        <mesh filename="package://adam_description/urdf/adam_u/meshes/shoulderRollLeft.STL" />
      </geometry>
    </collision>
  </link>
  <joint name="shoulderRoll_Left" type="revolute">
    <origin xyz="0.0335 0.0435 0" rpy="-0.34907 0 0" />
    <parent link="shoulderPitchLeft" />
    <child link="shoulderRollLeft" />
    <axis xyz="1 0 0" />
    <limit effort="65.0" lower="-0.575" upper="2.74" velocity="8.0" />
  </joint>
  <link name="shoulderYawLeft">
    <inertial>
      <origin xyz="-0.00123933726802084 -0.000681888153900939 -0.0955474692296238" rpy="0 0 0" />
      <mass value="0.185529092679341" />
      <inertia ixx="0.0010586892939199" ixy="1.22168114729863E-07" ixz="-1.31882940221163E-05"
        iyy="0.00102309851573098" iyz="-1.4354019667588E-05" izz="0.000131567719523138" />
    </inertial>
    <visual>
      <origin xyz="0 0 0" rpy="0 0 0" />
      <geometry>
        <mesh filename="package://adam_description/urdf/adam_u/meshes/shoulderYawLeft.STL" />
      </geometry>
      <material name="">
        <color rgba="1 1 1 1" />
      </material>
    </visual>
    <collision>
      <origin xyz="0 0 0" rpy="0 0 0" />
      <geometry>
        <mesh filename="package://adam_description/urdf/adam_u/meshes/shoulderYawLeft.STL" />
      </geometry>
    </collision>
  </link>
  <joint name="shoulderYaw_Left" type="revolute">
    <origin xyz="-0.0335 0.034 -0.0585" rpy="0 0 0" />
    <parent link="shoulderRollLeft" />
    <child link="shoulderYawLeft" />
    <axis xyz="0 0 1" />
    <limit effort="65.0" lower="-1.6" upper="1.6" velocity="8.0" />
  </joint>
  <link name="elbowLeft">
    <inertial>
      <origin xyz="-0.0164212953784719 0.0267255512854062 -0.0251647749784531" rpy="0 0 0" />
      <mass value="0.20283164852875" />
      <inertia ixx="0.000212761366293971" ixy="5.72552943989826E-06" ixz="-4.84599465482023E-05"
        iyy="0.00024737278693858" iyz="8.49666401342307E-06" izz="0.000143007917281259" />
    </inertial>
    <visual>
      <origin xyz="0 0 0" rpy="0 0 0" />
      <geometry>
        <mesh filename="package://adam_description/urdf/adam_u/meshes/elbowLeft.STL" />
      </geometry>
      <material name="">
        <color rgba="1 1 1 1" />
      </material>
    </visual>
    <collision>
      <origin xyz="0 0 0" rpy="0 0 0" />
      <geometry>
        <mesh filename="package://adam_description/urdf/adam_u/meshes/elbowLeft.STL" />
      </geometry>
    </collision>
  </link>
  <joint name="elbow_Left" type="revolute">
    <origin xyz="0 -0.0285 -0.20415" rpy="0 0 0" />
    <parent link="shoulderYawLeft" />
    <child link="elbowLeft" />
    <axis xyz="0 1 0" />
    <limit effort="30.0" lower="-2.0" upper="0.0" velocity="8.0" />
  </joint>
  <link name="wristYawLeft">
    <inertial>
      <origin xyz="-0.00202981 0.00013146 -0.09216894" rpy="0 0 0" />
      <mass value="0.95587869" />
      <inertia ixx="0.00256138" ixy="-0.00000268" ixz="0.00003060" iyy="0.00250125"
        iyz="-0.00002660" izz="0.00055105" />
    </inertial>
    <visual>
      <origin xyz="0 0 0" rpy="0 0 0" />
      <geometry>
        <mesh filename="package://adam_description/urdf/adam_u/meshes/wristYawLeft.dae" />
      </geometry>
      <material name="">
        <color rgba="1 1 1 1" />
      </material>
    </visual>
    <collision>
      <origin xyz="0 0 -0.09" rpy="0 0 0" />
      <geometry>
        <cylinder length="0.1" radius="0.038" />
      </geometry>
    </collision>
  </link>
  <joint name="wristYaw_Left" type="revolute">
    <origin xyz="-0.025 0.0285 -0.0729" rpy="0 0 0" />
    <parent link="elbowLeft" />
    <child link="wristYawLeft" />
    <axis xyz="0 0 1" />
    <limit effort="6.4" lower="-2.617" upper="2.617" velocity="4.9218" />
  </joint>
  <link name="wristPitchLeft">
    <inertial>
      <origin xyz="-0.00017580 0.00166098 -0.00002773" rpy="0 0 0" />
      <mass value="0.11963454" />
      <inertia ixx="0.00003359" ixy="0.00000002" ixz="0.00000000" iyy="0.00002690" iyz="-0.00000005"
        izz="0.00003977" />
    </inertial>
    <visual>
      <origin xyz="0 0 0" rpy="0 0 0" />
      <geometry>
        <mesh filename="package://adam_description/urdf/adam_u/meshes/wristPitchLeft.dae" />
      </geometry>
      <material name="">
        <color rgba="1 1 1 1" />
      </material>
    </visual>
  </link>
  <joint name="wristPitch_Left" type="revolute">
    <origin xyz="0 0 -0.2017" rpy="0 0 0" />
    <parent link="wristYawLeft" />
    <child link="wristPitchLeft" />
    <axis xyz="0 1 0" />
    <limit effort="6.4" lower="-0.907" upper="0.907" velocity="4.9218" />
  </joint>
  <link name="wristRollLeft">
    <inertial>
      <origin xyz="-0.00235135 -0.00073844 -0.07225815" rpy="0 0 0" />
      <mass value="0.48947265" />
      <inertia ixx="0.00044320" ixy="0.00000818" ixz="-0.00000581" iyy="0.00063365"
        iyz="-0.00001568" izz="0.00028512" />
    </inertial>
    <visual>
      <origin xyz="0 0 0" rpy="0 0 0" />
      <geometry>
        <mesh filename="package://adam_description/urdf/adam_u/meshes/inspire_Left.dae" />
      </geometry>
      <material name="">
        <color rgba="0.752941176470588 0.752941176470588 0.752941176470588 1" />
      </material>
    </visual>
    <collision>
      <origin xyz="0 0 0" rpy="0 0 0" />
      <geometry>
        <mesh filename="package://adam_description/urdf/adam_u/meshes/inspire_Left.dae" />
      </geometry>
    </collision>
  </link>
  <joint name="wristRoll_Left" type="revolute">
    <origin xyz="0 0 0" rpy="0 0 0" />
    <parent link="wristPitchLeft" />
    <child link="wristRollLeft" />
    <axis xyz="1 0 0" />
    <limit effort="6.4" lower="-0.907" upper="0.907" velocity="4.9218" />
  </joint>
  <link name="L_thumb_proximal_base">
    <inertial>
      <origin xyz="-0.0048772 0.00668 -0.00044071" rpy="0 0 0" />
      <mass value="0.0018869" />
      <inertia ixx="5.2003E-08" ixy="4.8353E-09" ixz="6.6444E-09" iyy="6.7434E-08" iyz="-5.4476E-10"
        izz="8.5319E-08" />
    </inertial>
    <visual>
      <origin xyz="0 0 0" rpy="0 0.3 0" />
      <geometry>
        <mesh filename="package://adam_description/urdf/adam_u/meshes/L_thumb_proximal_base.dae" />
      </geometry>
      <material name="">
        <color rgba="1 1 1 1" />
      </material>
    </visual>
    <collision>
      <origin xyz="0 0 0" rpy="0 0.3 0" />
      <geometry>
        <mesh filename="package://adam_description/urdf/adam_u/meshes/L_thumb_proximal_base.dae" />
      </geometry>
    </collision>
  </link>
  <joint name="L_thumb_MCP_joint1" type="revolute">
    <origin xyz="0.020450106 -0.016955517 -0.045202411" rpy="-1.5708 0 2.9722026" />
    <parent link="wristRollLeft" />
    <child link="L_thumb_proximal_base" />
    <axis xyz="0 1 0" />
    <limit lower="0" upper="1.1" effort="1.0" velocity="1" />
  </joint>
  <link name="L_thumb_proximal">
    <inertial>
      <origin xyz="-3.8578E-05 0.025335 0.0016982" rpy="0 0 0" />
      <mass value="0.0066101" />
      <inertia ixx="2.787E-06" ixy="1.3042E-10" ixz="1.3413E-09" iyy="8.9435E-07" iyz="2.1426E-07"
        izz="2.4105E-06" />
    </inertial>
    <visual>
      <origin xyz="0 0 0" rpy="0 0 0" />
      <geometry>
        <mesh filename="package://adam_description/urdf/adam_u/meshes/L_thumb_proximal.dae" />
      </geometry>
      <material name="">
        <color rgba="1 1 1 1" />
      </material>
    </visual>
    <collision>
      <origin xyz="0 0 0" rpy="0 0 0" />
      <geometry>
        <mesh filename="package://adam_description/urdf/adam_u/meshes/L_thumb_proximal.dae" />
      </geometry>
    </collision>
  </link>
  <joint name="L_thumb_MCP_joint2" type="revolute">
    <origin xyz="-0.0115 0.005 0.0034" rpy="0.5948037 -1.2708 0" />
    <parent link="L_thumb_proximal_base" />
    <child link="L_thumb_proximal" />
    <axis xyz="-1 0 0" />
    <limit lower="0" upper="0.5" effort="1.0" velocity="1" />
  </joint>
  <link name="L_thumb_intermediate">
    <inertial>
      <origin xyz="-1.7401E-07 0.0072516 0.0064286" rpy="0 0 0" />
      <mass value="0.0037844" />
      <inertia ixx="4.6532E-07" ixy="-9.1152E-13" ixz="-3.8682E-12" iyy="2.6856E-07"
        iyz="6.4144E-08" izz="4.252E-07" />
    </inertial>
    <visual>
      <origin xyz="0 0 0" rpy="0 0 0" />
      <geometry>
        <mesh filename="package://adam_description/urdf/adam_u/meshes/L_thumb_intermediate.dae" />
      </geometry>
      <material name="">
        <color rgba="1 1 1 1" />
      </material>
    </visual>
    <collision>
      <origin xyz="0 0 0" rpy="0 0 0" />
      <geometry>
        <mesh filename="package://adam_description/urdf/adam_u/meshes/L_thumb_intermediate.dae" />
      </geometry>
    </collision>
  </link>
  <joint name="L_thumb_PIP_joint" type="revolute">
    <origin xyz="0 0.055863 -0.0039241" rpy="0.038299 0 0" />
    <parent link="L_thumb_proximal" />
    <child link="L_thumb_intermediate" />
    <axis xyz="-1 0 0" />
    <limit lower="0" upper="1" effort="1.0" velocity="1" />
  </joint>
  <link name="L_thumb_distal">
    <inertial>
      <origin xyz="-3.3076E-06 0.010511 0.00057861" rpy="0 0 0" />
      <mass value="0.003344" />
      <inertia ixx="2.0026E-07" ixy="-1.4157E-10" ixz="5.6213E-11" iyy="8.7108E-08" iyz="2.4414E-08"
        izz="1.8974E-07" />
    </inertial>
    <visual>
      <origin xyz="0 0 0" rpy="0 0 0" />
      <geometry>
        <mesh filename="package://adam_description/urdf/adam_u/meshes/L_thumb_distal.dae" />
      </geometry>
      <material name="">
        <color rgba="1 1 1 1" />
      </material>
    </visual>
    <collision>
      <origin xyz="0 0 0" rpy="0 0 0" />
      <geometry>
        <mesh filename="package://adam_description/urdf/adam_u/meshes/L_thumb_distal.dae" />
      </geometry>
    </collision>
  </link>
  <joint name="L_thumb_DIP_joint" type="revolute">
    <origin xyz="0 0.022558 0.0020717" rpy="0.011642 0 0" />
    <parent link="L_thumb_intermediate" />
    <child link="L_thumb_distal" />
    <axis xyz="-1 0 0" />
    <limit lower="0" upper="1.2" effort="1.0" velocity="1" />
  </joint>
  <link name="L_index_proximal">
    <inertial>
      <origin xyz="0.0080456 0.011884 -0.0016957" rpy="0 0 0" />
      <mass value="0.0042405" />
      <inertia ixx="6.9402E-07" ixy="1.4654E-11" ixz="-2.3231E-12" iyy="2.3041E-07" iyz="9.1802E-08"
        izz="6.4342E-07" />
    </inertial>
    <visual>
      <origin xyz="0 0 0" rpy="0 0 0" />
      <geometry>
        <mesh filename="package://adam_description/urdf/adam_u/meshes/L_index_proximal.dae" />
      </geometry>
      <material name="">
        <color rgba="1 1 1 1" />
      </material>
    </visual>
    <collision>
      <origin xyz="0 0 0" rpy="0 0 0" />
      <geometry>
        <mesh filename="package://adam_description/urdf/adam_u/meshes/L_index_proximal.dae" />
      </geometry>
    </collision>
  </link>
  <joint name="L_index_MCP_joint" type="revolute">
    <origin xyz="0.018231106 0.000284483 -0.127012411" rpy="-1.3208 -0.034907 0" />
    <parent link="wristRollLeft" />
    <child link="L_index_proximal" />
    <axis xyz="-1 0 0" />
    <limit lower="0" upper="1.7" effort="1.0" velocity="1" />
  </joint>
  <link name="L_index_distal">
    <inertial>
      <origin xyz="0.0063917 0.01959 -0.0019564" rpy="0 0 0" />
      <mass value="0.0045682" />
      <inertia ixx="7.8176E-07" ixy="-7.7162E-14" ixz="3.9272E-13" iyy="1.5634E-07" iyz="2.1006E-07"
        izz="7.0081E-07" />
    </inertial>
    <visual>
      <origin xyz="0 0 0" rpy="0 0 0" />
      <geometry>
        <mesh filename="package://adam_description/urdf/adam_u/meshes/L_index_distal.dae" />
      </geometry>
      <material name="">
        <color rgba="1 1 1 1" />
      </material>
    </visual>
    <collision>
      <origin xyz="0 0 0" rpy="0 0 0" />
      <geometry>
        <mesh filename="package://adam_description/urdf/adam_u/meshes/L_index_distal.dae" />
      </geometry>
    </collision>
  </link>
  <joint name="L_index_DIP_joint" type="revolute">
    <origin xyz="0.0016538 0.030445 -0.010275" rpy="-0.039748 0 0" />
    <parent link="L_index_proximal" />
    <child link="L_index_distal" />
    <axis xyz="-1 0 0" />
    <limit lower="0" upper="1.6" effort="1.0" velocity="1" />
  </joint>
  <link name="L_middle_proximal">
    <inertial>
      <origin xyz="0.0080653 0.011884 -0.0016957" rpy="0 0 0" />
      <mass value="0.0042405" />
      <inertia ixx="6.9402E-07" ixy="1.4338E-11" ixz="-2.3917E-12" iyy="2.3041E-07" iyz="9.1802E-08"
        izz="6.4342E-07" />
    </inertial>
    <visual>
      <origin xyz="0 0 0" rpy="0 0 0" />
      <geometry>
        <mesh filename="package://adam_description/urdf/adam_u/meshes/L_middle_proximal.dae" />
      </geometry>
      <material name="">
        <color rgba="1 1 1 1" />
      </material>
    </visual>
    <collision>
      <origin xyz="0 0 0" rpy="0 0 0" />
      <geometry>
        <mesh filename="package://adam_description/urdf/adam_u/meshes/L_middle_proximal.dae" />
      </geometry>
    </collision>
  </link>
  <joint name="L_middle_MCP_joint" type="revolute">
    <origin xyz="-0.001114894 0.000284483 -0.127012411" rpy="-1.3208 0 0" />
    <parent link="wristRollLeft" />
    <child link="L_middle_proximal" />
    <axis xyz="-1 0 0" />
    <limit lower="0" upper="1.7" effort="1.0" velocity="1" />
  </joint>
  <link name="L_middle_distal">
    <inertial>
      <origin xyz="0.0063955 0.020807 -0.0018039" rpy="0 0 0" />
      <mass value="0.0050397" />
      <inertia ixx="9.8385E-07" ixy="-4.0683E-12" ixz="-1.7233E-12" iyy="1.7328E-07"
        iyz="2.5594E-07" izz="8.9141E-07" />
    </inertial>
    <visual>
      <origin xyz="0 0 0" rpy="0 0 0" />
      <geometry>
        <mesh filename="package://adam_description/urdf/adam_u/meshes/L_middle_distal.dae" />
      </geometry>
      <material name="">
        <color rgba="1 1 1 1" />
      </material>
    </visual>
    <collision>
      <origin xyz="0 0 0" rpy="0 0 0" />
      <geometry>
        <mesh filename="package://adam_description/urdf/adam_u/meshes/L_middle_distal.dae" />
      </geometry>
    </collision>
  </link>
  <joint name="L_middle_DIP_joint" type="revolute">
    <origin xyz="0.0016698 0.030445 -0.010275" rpy="-0.071413 0 0" />
    <parent link="L_middle_proximal" />
    <child link="L_middle_distal" />
    <axis xyz="-1 0 0" />
    <limit lower="0" upper="1.6" effort="1.0" velocity="1" />
  </joint>
  <link name="L_ring_proximal">
    <inertial>
      <origin xyz="0.010821 0.011884 -0.0016957" rpy="0 0 0" />
      <mass value="0.0042405" />
      <inertia ixx="6.9402E-07" ixy="1.3923E-11" ixz="-2.5637E-12" iyy="2.3041E-07" iyz="9.1802E-08"
        izz="6.4342E-07" />
    </inertial>
    <visual>
      <origin xyz="0 0 0" rpy="0 0 0" />
      <geometry>
        <mesh filename="package://adam_description/urdf/adam_u/meshes/L_ring_proximal.dae" />
      </geometry>
      <material name="">
        <color rgba="1 1 1 1" />
      </material>
    </visual>
    <collision>
      <origin xyz="0 0 0" rpy="0 0 0" />
      <geometry>
        <mesh filename="package://adam_description/urdf/adam_u/meshes/L_ring_proximal.dae" />
      </geometry>
    </collision>
  </link>
  <joint name="L_ring_MCP_joint" type="revolute">
    <origin xyz="-0.023084894 0.000284483 -0.126032411" rpy="-1.3208 0.05236 0" />
    <parent link="wristRollLeft" />
    <child link="L_ring_proximal" />
    <axis xyz="-1 0 0" />
    <limit lower="0" upper="1.7" effort="1.0" velocity="1" />
  </joint>
  <link name="L_ring_distal">
    <inertial>
      <origin xyz="0.009285 0.019591 -0.0019565" rpy="0 0 0" />
      <mass value="0.0045682" />
      <inertia ixx="7.8176E-07" ixy="4.4486E-13" ixz="-6.071E-14" iyy="1.5634E-07" iyz="2.1006E-07"
        izz="7.0081E-07" />
    </inertial>
    <visual>
      <origin xyz="0 0 0" rpy="0 0 0" />
      <geometry>
        <mesh filename="package://adam_description/urdf/adam_u/meshes/L_ring_distal.dae" />
      </geometry>
      <material name="">
        <color rgba="1 1 1 1" />
      </material>
    </visual>
    <collision>
      <origin xyz="0 0 0" rpy="0 0 0" />
      <geometry>
        <mesh filename="package://adam_description/urdf/adam_u/meshes/L_ring_distal.dae" />
      </geometry>
    </collision>
  </link>
  <joint name="L_ring_DIP_joint" type="revolute">
    <origin xyz="0.0015355 0.030445 -0.010275" rpy="-0.039748 0 0" />
    <parent link="L_ring_proximal" />
    <child link="L_ring_distal" />
    <axis xyz="-1 0 0" />
    <limit lower="0" upper="1.6" effort="1.0" velocity="1" />
  </joint>
  <link name="L_pinky_proximal">
    <inertial>
      <origin xyz="0.013546 0.011884 -0.0016957" rpy="0 0 0" />
      <mass value="0.0042405" />
      <inertia ixx="6.9402E-07" ixy="1.4088E-11" ixz="-2.5363E-12" iyy="2.3041E-07" iyz="9.1802E-08"
        izz="6.4342E-07" />
    </inertial>
    <visual>
      <origin xyz="0 0 0" rpy="0 0 0" />
      <geometry>
        <mesh filename="package://adam_description/urdf/adam_u/meshes/L_pinky_proximal.dae" />
      </geometry>
      <material name="">
        <color rgba="1 1 1 1" />
      </material>
    </visual>
    <collision>
      <origin xyz="0 0 0" rpy="0 0 0" />
      <geometry>
        <mesh filename="package://adam_description/urdf/adam_u/meshes/L_pinky_proximal.dae" />
      </geometry>
    </collision>
  </link>
  <joint name="L_pinky_MCP_joint" type="revolute">
    <origin xyz="-0.044926894 0.000284483 -0.123672411" rpy="-1.3208 0.10472 0" />
    <parent link="wristRollLeft" />
    <child link="L_pinky_proximal" />
    <axis xyz="-1 0 0" />
    <limit lower="0" upper="1.7" effort="1.0" velocity="1" />
  </joint>
  <link name="L_pinky_distal">
    <inertial>
      <origin xyz="0.013546 0.016245 -0.0022219" rpy="0 0 0" />
      <mass value="0.0036036" />
      <inertia ixx="4.4881E-07" ixy="-2.6544E-12" ixz="2.0643E-12" iyy="1.2252E-07" iyz="1.3507E-07"
        izz="3.8703E-07" />
    </inertial>
    <visual>
      <origin xyz="0 0 0" rpy="0 0 0" />
      <geometry>
        <mesh filename="package://adam_description/urdf/adam_u/meshes/L_pinky_distal.dae" />
      </geometry>
      <material name="">
        <color rgba="1 1 1 1" />
      </material>
    </visual>
    <collision>
      <origin xyz="0 0 0" rpy="0 0 0" />
      <geometry>
        <mesh filename="package://adam_description/urdf/adam_u/meshes/L_pinky_distal.dae" />
      </geometry>
    </collision>
  </link>
  <joint name="L_pinky_DIP_joint" type="revolute">
    <origin xyz="0 0.030445 -0.010275" rpy="0.037691 0 0" />
    <parent link="L_pinky_proximal" />
    <child link="L_pinky_distal" />
    <axis xyz="-1 0 0" />
    <limit lower="0" upper="1.6" effort="1.0" velocity="1" />
  </joint>
  <link name="shoulderPitchRight">
    <inertial>
      <origin xyz="-0.00143759910032871 -0.0268503054182294 0.000107836180958006" rpy="0 0 0" />
      <mass value="0.0738851150862316" />
      <inertia ixx="6.19354220142105E-05" ixy="-1.57306561088929E-06" ixz="2.35053464087437E-07"
        iyy="0.000105123332365382" iyz="1.56709023638239E-07" izz="0.000125040168674664" />
    </inertial>
    <visual>
      <origin xyz="0 0 0" rpy="0 0 0" />
      <geometry>
        <mesh filename="package://adam_description/urdf/adam_u/meshes/shoulderPitchRight.STL" />
      </geometry>
      <material name="">
        <color rgba="1 1 1 1" />
      </material>
    </visual>
    <collision>
      <origin xyz="0 0 0" rpy="0 0 0" />
      <geometry>
        <mesh filename="package://adam_description/urdf/adam_u/meshes/shoulderPitchRight.STL" />
      </geometry>
    </collision>
  </link>
  <joint name="shoulderPitch_Right" type="revolute">
    <origin xyz="0 -0.160489476847415 0.257553661893028" rpy="-0.349065850398898 0 0" />
    <parent link="torso" />
    <child link="shoulderPitchRight" />
    <axis xyz="0 1 0" />
    <limit effort="65.0" lower="-3.560" upper="1.989" velocity="8.0" />
  </joint>
  <link name="shoulderRollRight">
    <inertial>
      <origin xyz="-0.0277962218849738 -0.0115150626121273 -0.0146453977073513" rpy="0 0 0" />
      <mass value="0.140495543564482" />
      <inertia ixx="0.000177929600527355" ixy="-6.7495359946587E-06" ixz="-9.89024488213538E-06"
        iyy="0.00013803562901708" iyz="-4.9576600591171E-05" izz="0.000117957610397269" />
    </inertial>
    <visual>
      <origin xyz="0 0 0" rpy="0 0 0" />
      <geometry>
        <mesh filename="package://adam_description/urdf/adam_u/meshes/shoulderRollRight.STL" />
      </geometry>
      <material name="">
        <color rgba="1 1 1 1" />
      </material>
    </visual>
    <collision>
      <origin xyz="0 0 0" rpy="0 0 0" />
      <geometry>
        <mesh filename="package://adam_description/urdf/adam_u/meshes/shoulderRollRight.STL" />
      </geometry>
    </collision>
  </link>
  <joint name="shoulderRoll_Right" type="revolute">
    <origin xyz="0.033500000000041 -0.0434999999999418 0" rpy="0.349065850398898 0 0" />
    <parent link="shoulderPitchRight" />
    <child link="shoulderRollRight" />
    <axis xyz="1 0 0" />
    <limit effort="65.0" lower="-2.74" upper="0.575" velocity="8.0" />
  </joint>
  <link name="shoulderYawRight">
    <inertial>
      <origin xyz="-0.00123465291254691 0.00068674340021091 -0.0954921731458966" rpy="0 0 0" />
      <mass value="0.185374090089433" />
      <inertia ixx="0.00105802905047363" ixy="-1.22441700884994E-07" ixz="-1.31331509452719E-05"
        iyy="0.00102243822451776" iyz="1.43475440511398E-05" izz="0.000131512811160992" />
    </inertial>
    <visual>
      <origin xyz="0 0 0" rpy="0 0 0" />
      <geometry>
        <mesh filename="package://adam_description/urdf/adam_u/meshes/shoulderYawRight.STL" />
      </geometry>
      <material name="">
        <color rgba="1 1 1 1" />
      </material>
    </visual>
    <collision>
      <origin xyz="0 0 0" rpy="0 0 0" />
      <geometry>
        <mesh filename="package://adam_description/urdf/adam_u/meshes/shoulderYawRight.STL" />
      </geometry>
    </collision>
  </link>
  <joint name="shoulderYaw_Right" type="revolute">
    <origin xyz="-0.0335000000014145 -0.0340000000005376 -0.0585000000006807" rpy="0 0 0" />
    <parent link="shoulderRollRight" />
    <child link="shoulderYawRight" />
    <axis xyz="0 0 1" />
    <limit effort="65.0" lower="-1.6" upper="1.6" velocity="8.0" />
  </joint>
  <link name="elbowRight">
    <inertial>
      <origin xyz="-0.0163814146402827 -0.0267980572712556 -0.0251639997738968" rpy="0 0 0" />
      <mass value="0.202831341443703" />
      <inertia ixx="0.000212821991138584" ixy="-5.85163683124709E-06" ixz="-4.87575565533841E-05"
        iyy="0.000247643848291084" iyz="-8.57383707982377E-06" izz="0.00014332038303259" />
    </inertial>
    <visual>
      <origin xyz="0 0 0" rpy="0 0 0" />
      <geometry>
        <mesh filename="package://adam_description/urdf/adam_u/meshes/elbowRight.STL" />
      </geometry>
      <material name="">
        <color rgba="1 1 1 1" />
      </material>
    </visual>
    <collision>
      <origin xyz="0 0 0" rpy="0 0 0" />
      <geometry>
        <mesh filename="package://adam_description/urdf/adam_u/meshes/elbowRight.STL" />
      </geometry>
    </collision>
  </link>
  <joint name="elbow_Right" type="revolute">
    <origin xyz="0 0.0284999999999329 -0.204149999999879" rpy="0 0 0" />
    <parent link="shoulderYawRight" />
    <child link="elbowRight" />
    <axis xyz="0 1 0" />
    <limit effort="30.0" lower="-2.0" upper="0.0" velocity="8.0" />
  </joint>
  <link name="wristYawRight">
    <inertial>
      <origin xyz="-0.00202981 -0.00013146 -0.09216894" rpy="0 0 0" />
      <mass value="0.95587832" />
      <inertia ixx="0.00256092" ixy="0.00000273" ixz="0.00003067" iyy="0.00250028" iyz="0.00002722"
        izz="0.00055059" />
    </inertial>
    <visual>
      <origin xyz="0 0 0" rpy="0 0 0" />
      <geometry>
        <mesh filename="package://adam_description/urdf/adam_u/meshes/wristYawRight.dae" />
      </geometry>
      <material name="">
        <color rgba="1 1 1 1" />
      </material>
    </visual>
    <collision>
      <origin xyz="0 0 -0.09" rpy="0 0 0" />
      <geometry>
        <cylinder length="0.1" radius="0.038" />
      </geometry>
    </collision>
  </link>
  <joint name="wristYaw_Right" type="revolute">
    <origin xyz="-0.025 -0.0285 -0.0729" rpy="0 0 0" />
    <parent link="elbowRight" />
    <child link="wristYawRight" />
    <axis xyz="0 0 1" />
    <limit effort="6.4" lower="-2.617" upper="2.617" velocity="4.9218" />
  </joint>
  <link name="wristPitchRight">
    <inertial>
      <origin xyz="-0.00017580 0.00166098 -0.00002773" rpy="0 0 0" />
      <mass value="0.11963454" />
      <inertia ixx="0.00003359" ixy="0.00000002" ixz="0.00000000" iyy="0.00002690" iyz="-0.00000005"
        izz="0.00003977" />
    </inertial>
    <visual>
      <origin xyz="0 0 0" rpy="0 0 0" />
      <geometry>
        <mesh filename="package://adam_description/urdf/adam_u/meshes/wristPitchRight.dae" />
      </geometry>
      <material name="">
        <color rgba="1 1 1 1" />
      </material>
    </visual>
  </link>
  <joint name="wristPitch_Right" type="revolute">
    <origin xyz="0 0 -0.201699999719004" rpy="0 0 0" />
    <parent link="wristYawRight" />
    <child link="wristPitchRight" />
    <axis xyz="0 1 0" />
    <limit effort="6.4" lower="-0.907" upper="0.907" velocity="4.9218" />
  </joint>
  <link name="wristRollRight">
    <inertial>
      <origin xyz="-0.00235219 0.00073858 -0.07225807" rpy="0 0 0" />
      <mass value="0.48947185" />
      <inertia ixx="0.00044319" ixy="-0.00000818" ixz="-0.00000581" iyy="0.00063364"
        iyz="0.00001568" izz="0.00028512" />
    </inertial>
    <visual>
      <origin xyz="0 0 0" rpy="0 0 0" />
      <geometry>
        <mesh filename="package://adam_description/urdf/adam_u/meshes/inspire_Right.dae" />
      </geometry>
      <material name="">
        <color rgba="0.752941176470588 0.752941176470588 0.752941176470588 1" />
      </material>
    </visual>
    <collision>
      <origin xyz="0 0 0" rpy="0 0 0" />
      <geometry>
        <mesh filename="package://adam_description/urdf/adam_u/meshes/inspire_Right.dae" />
      </geometry>
    </collision>
  </link>
  <joint name="wristRoll_Right" type="revolute">
    <origin xyz="0 0 0" rpy="0 0 0" />
    <parent link="wristPitchRight" />
    <child link="wristRollRight" />
    <axis xyz="1 0 0" />
    <limit effort="6.4" lower="-0.907" upper="0.907" velocity="4.9218" />
  </joint>
  <link name="R_thumb_proximal_base">
    <inertial>
      <origin xyz="-0.00382764881053596 -0.0107181618219411 0.000559765736006684" rpy="0 0 0" />
      <mass value="0.00151773698887962" />
      <inertia ixx="3.60087080879981E-08" ixy="-1.96095506259986E-09" ixz="-5.66955703371013E-09"
        iyy="5.6161096564387E-08" iyz="-1.99374406008934E-10" izz="6.0787820658132E-08" />
    </inertial>
    <visual>
      <origin xyz="0 0 0" rpy="0 0 0" />
      <geometry>
        <mesh filename="package://adam_description/urdf/adam_u/meshes/R_thumb_proximal_base.dae" />
      </geometry>
      <material name="">
        <color rgba="0.752941176470588 0.752941176470588 0.752941176470588 1" />
      </material>
    </visual>
    <collision>
      <origin xyz="0 0 0" rpy="0 0 0" />
      <geometry>
        <mesh filename="package://adam_description/urdf/adam_u/meshes/R_thumb_proximal_base.dae" />
      </geometry>
    </collision>
  </link>
  <joint name="R_thumb_MCP_joint1" type="revolute">
    <origin xyz="0.0204501060000028 0.0169555170000098 -0.061693589"
      rpy="-1.57078530718744 0 -2.67727777418532" />
    <parent link="wristRollRight" />
    <child link="R_thumb_proximal_base" />
    <axis xyz="0 -1 0" />
    <limit lower="0" upper="1.1" effort="1.0" velocity="1" />
  </joint>
  <link name="R_thumb_proximal">
    <inertial>
      <origin xyz="-0.000117809754724056 0.0258571423805095 -0.00100758942644689" rpy="0 0 0" />
      <mass value="0.0261115841107002" />
      <inertia ixx="7.93931587879801E-06" ixy="1.48009708452218E-08" ixz="-3.38204029822359E-09"
        iyy="2.41312609527012E-06" iyz="-1.30100404690884E-07" izz="6.72250735621506E-06" />
    </inertial>
    <visual>
      <origin xyz="0 0 0" rpy="0 0 0" />
      <geometry>
        <mesh filename="package://adam_description/urdf/adam_u/meshes/R_thumb_proximal.dae" />
      </geometry>
      <material name="">
        <color rgba="0.752941176470588 0.752941176470588 0.752941176470588 1" />
      </material>
    </visual>
    <collision>
      <origin xyz="0 0 0" rpy="0 0 0" />
      <geometry>
        <mesh filename="package://adam_description/urdf/adam_u/meshes/R_thumb_proximal.dae" />
      </geometry>
    </collision>
  </link>
  <joint name="R_thumb_MCP_joint2" type="revolute">
    <origin xyz="-0.0114999999999978 -0.011843 0"
      rpy="2.41138809480577 1.57079265360577 3.14159265198266" />
    <parent link="R_thumb_proximal_base" />
    <child link="R_thumb_proximal" />
    <axis xyz="1 0 0" />
    <limit lower="0" upper="0.5" effort="1.0" velocity="1" />
  </joint>
  <link name="R_thumb_intermediate">
    <inertial>
      <origin xyz="-0.000229619674236775 0.00972594453741249 -0.0056973693761041" rpy="0 0 0" />
      <mass value="0.00762416186974198" />
      <inertia ixx="8.63217330998741E-07" ixy="1.18238650825234E-09" ixz="4.34180082922964E-11"
        iyy="3.66252085743616E-07" iyz="-8.29334502637433E-08" izz="7.95816234979935E-07" />
    </inertial>
    <visual>
      <origin xyz="0 0 0" rpy="0 0 0" />
      <geometry>
        <mesh filename="package://adam_description/urdf/adam_u/meshes/R_thumb_intermediate.dae" />
      </geometry>
      <material name="">
        <color rgba="0.752941176470588 0.752941176470588 0.752941176470588 1" />
      </material>
    </visual>
    <collision>
      <origin xyz="0 0 0" rpy="0 0 0" />
      <geometry>
        <mesh filename="package://adam_description/urdf/adam_u/meshes/R_thumb_intermediate.dae" />
      </geometry>
    </collision>
  </link>
  <joint name="R_thumb_PIP_joint" type="revolute">
    <origin xyz="0 0.0558629999999866 0.00392410000000695" rpy="-0.0382990000074394 0 0" />
    <parent link="R_thumb_proximal" />
    <child link="R_thumb_intermediate" />
    <axis xyz="1 0 0" />
    <limit lower="0" upper="1" effort="1.0" velocity="1" />
  </joint>
  <link name="R_thumb_distal">
    <inertial>
      <origin xyz="-0.000295905109829989 0.0107670545015768 -0.00301220801911901" rpy="0 0 0" />
      <mass value="0.00320232682951003" />
      <inertia ixx="1.86499290413194E-07" ixy="3.07936668015311E-10" ixz="-1.45970263564255E-11"
        iyy="7.66299569611685E-08" iyz="-2.44638579134461E-09" izz="1.79862828526633E-07" />
    </inertial>
    <visual>
      <origin xyz="0 0 0" rpy="0 0 0" />
      <geometry>
        <mesh filename="package://adam_description/urdf/adam_u/meshes/R_thumb_distal.dae" />
      </geometry>
      <material name="">
        <color rgba="0.752941176470588 0.752941176470588 0.752941176470588 1" />
      </material>
    </visual>
    <collision>
      <origin xyz="0 0 0" rpy="0 0 0" />
      <geometry>
        <mesh filename="package://adam_description/urdf/adam_u/meshes/R_thumb_distal.dae" />
      </geometry>
    </collision>
  </link>
  <joint name="R_thumb_DIP_joint" type="revolute">
    <origin xyz="0 0.0225579999999965 -0.00207169999999632" rpy="-0.0116419999984538 0 0" />
    <parent link="R_thumb_intermediate" />
    <child link="R_thumb_distal" />
    <axis xyz="1 0 0" />
    <limit lower="0" upper="1.2" effort="1.0" velocity="1" />
  </joint>
  <link name="R_index_proximal">
    <inertial>
      <origin xyz="0.00990135500742561 0.0133304136652114 0.00117936285982397" rpy="0 0 0" />
      <mass value="0.00701852522150007" />
      <inertia ixx="8.95726613028746E-07" ixy="-1.148920094866E-11" ixz="-3.18020240179009E-12"
        iyy="2.82953699148337E-07" iyz="-7.1219419325933E-08" izz="8.2572074500356E-07" />
    </inertial>
    <visual>
      <origin xyz="0 0 0" rpy="0 0 0" />
      <geometry>
        <mesh filename="package://adam_description/urdf/adam_u/meshes/R_index_proximal.dae" />
      </geometry>
      <material name="">
        <color rgba="0.752941176470588 0.752941176470588 0.752941176470588 1" />
      </material>
    </visual>
    <collision>
      <origin xyz="0 0 0" rpy="0 0 0" />
      <geometry>
        <mesh filename="package://adam_description/urdf/adam_u/meshes/R_index_proximal.dae" />
      </geometry>
    </collision>
  </link>
  <joint name="R_index_MCP_joint" type="revolute">
    <origin xyz="0.016376105999999 -0.000284482999995478 -0.127082589000005"
      rpy="-1.81478530717884 -0.0349070000000007 0" />
    <parent link="wristRollRight" />
    <child link="R_index_proximal" />
    <axis xyz="1 0 0" />
    <limit lower="0" upper="1.7" effort="1.0" velocity="1" />
  </joint>
  <link name="R_index_distal">
    <inertial>
      <origin xyz="0.00832615978706599 0.0195854179080407 -0.00337709473418676" rpy="0 0 0" />
      <mass value="0.00444688526691259" />
      <inertia ixx="7.46210721263786E-07" ixy="2.73612209843274E-12" ixz="2.55720470783722E-12"
        iyy="1.05450954689884E-07" iyz="-1.30534943168026E-07" izz="7.09638477603336E-07" />
    </inertial>
    <visual>
      <origin xyz="0 0 0" rpy="0 0 0" />
      <geometry>
        <mesh filename="package://adam_description/urdf/adam_u/meshes/R_index_distal.dae" />
      </geometry>
      <material name="">
        <color rgba="0.752941176470588 0.752941176470588 0.752941176470588 1" />
      </material>
    </visual>
    <collision>
      <origin xyz="0 0 0" rpy="0 0 0" />
      <geometry>
        <mesh filename="package://adam_description/urdf/adam_u/meshes/R_index_distal.dae" />
      </geometry>
    </collision>
  </link>
  <joint name="R_index_DIP_joint" type="revolute">
    <origin xyz="0.00157500000000335 0.0304450000000037 0.0102749999999737"
      rpy="0.0442880000000218 0 0" />
    <parent link="R_index_proximal" />
    <child link="R_index_distal" />
    <axis xyz="1 0 0" />
    <limit lower="0" upper="1.6" effort="1.0" velocity="1" />
  </joint>
  <link name="R_index_distalR_middle_proximal">
    <inertial>
      <origin xyz="0.00806492053336038 0.0133239385273582 0.00125954670221406" rpy="0 0 0" />
      <mass value="0.0070185317558805" />
      <inertia ixx="8.95728553122376E-07" ixy="-1.15940626961654E-11" ixz="-3.42128943781823E-12"
        iyy="2.83828882925209E-07" iyz="-7.44723781455968E-08" izz="8.24847413087409E-07" />
    </inertial>
    <visual>
      <origin xyz="0 0 0" rpy="0 0 0" />
      <geometry>
        <mesh filename="package://adam_description/urdf/adam_u/meshes/R_index_distalR_middle_proximal.dae" />
      </geometry>
      <material name="">
        <color rgba="0.752941176470588 0.752941176470588 0.752941176470588 1" />
      </material>
    </visual>
    <collision>
      <origin xyz="0 0 0" rpy="0 0 0" />
      <geometry>
        <mesh filename="package://adam_description/urdf/adam_u/meshes/R_index_distalR_middle_proximal.dae" />
      </geometry>
    </collision>
  </link>
  <joint name="R_middle_MCP_joint" type="revolute">
    <origin xyz="-0.001114893999998 -0.000284483000066449 -0.127099588999977"
      rpy="-1.82078530717921 0 0" />
    <parent link="wristRollRight" />
    <child link="R_index_distalR_middle_proximal" />
    <axis xyz="1 0 0" />
    <limit lower="0" upper="1.7" effort="1.0" velocity="1" />
  </joint>
  <link name="R_middle_distal">
    <inertial>
      <origin xyz="0.00639764910329568 0.0207583299109729 -0.00344503193080434" rpy="0 0 0" />
      <mass value="0.00489152423458158" />
      <inertia ixx="9.68779716193073E-07" ixy="1.00103343518395E-11" ixz="2.13540088399477E-12"
        iyy="1.12860193633169E-07" iyz="-1.470662072756E-07" izz="9.31723000066164E-07" />
    </inertial>
    <visual>
      <origin xyz="0 0 0" rpy="0 0 0" />
      <geometry>
        <mesh filename="package://adam_description/urdf/adam_u/meshes/R_middle_distal.dae" />
      </geometry>
      <material name="">
        <color rgba="0.752941176470588 0.752941176470588 0.752941176470588 1" />
      </material>
    </visual>
    <collision>
      <origin xyz="0 0 0" rpy="0 0 0" />
      <geometry>
        <mesh filename="package://adam_description/urdf/adam_u/meshes/R_middle_distal.dae" />
      </geometry>
    </collision>
  </link>
  <joint name="R_middle_DIP_joint" type="revolute">
    <origin xyz="0.00166729999999888 0.0304450000000022 0.0102750000000512"
      rpy="0.0714130000000114 0 0" />
    <parent link="R_index_distalR_middle_proximal" />
    <child link="R_middle_distal" />
    <axis xyz="1 0 0" />
    <limit lower="0" upper="1.6" effort="1.0" velocity="1" />
  </joint>
  <link name="R_ring_proximal">
    <inertial>
      <origin xyz="0.00802083529366671 0.0132340178107531 0.00156645676513759" rpy="0 0 0" />
      <mass value="0.00658140314195911" />
      <inertia ixx="8.77699356489043E-07" ixy="-7.2724341496541E-12" ixz="-3.16350537979834E-12"
        iyy="2.70922365687212E-07" iyz="-7.67818147493719E-08" izz="8.15640213128758E-07" />
    </inertial>
    <visual>
      <origin xyz="0 0 0" rpy="0 0 0" />
      <geometry>
        <mesh filename="package://adam_description/urdf/adam_u/meshes/R_ring_proximal.dae" />
      </geometry>
      <material name="">
        <color rgba="0.752941176470588 0.752941176470588 0.752941176470588 1" />
      </material>
    </visual>
    <collision>
      <origin xyz="0 0 0" rpy="0 0 0" />
      <geometry>
        <mesh filename="package://adam_description/urdf/adam_u/meshes/R_ring_proximal.dae" />
      </geometry>
    </collision>
  </link>
  <joint name="R_ring_MCP_joint" type="revolute">
    <origin xyz="-0.020288893999997 -0.000284483000030838 -0.126176588999991"
      rpy="-1.82078530717921 0.0523599999999982 0" />
    <parent link="wristRollRight" />
    <child link="R_ring_proximal" />
    <axis xyz="1 0 0" />
    <limit lower="0" upper="1.7" effort="1.0" velocity="1" />
  </joint>
  <link name="R_ring_distal">
    <inertial>
      <origin xyz="0.00802088818080873 0.0195658921497007 -0.00298540872724894" rpy="0 0 0" />
      <mass value="0.00444671038889567" />
      <inertia ixx="7.46188128027768E-07" ixy="9.86567206698211E-12" ixz="3.65302430361656E-12"
        iyy="1.08263786700982E-07" iyz="-1.368703521112E-07" izz="7.06800623149926E-07" />
    </inertial>
    <visual>
      <origin xyz="0 0 0" rpy="0 0 0" />
      <geometry>
        <mesh filename="package://adam_description/urdf/adam_u/meshes/R_ring_distal.dae" />
      </geometry>
      <material name="">
        <color rgba="0.752941176470588 0.752941176470588 0.752941176470588 1" />
      </material>
    </visual>
    <collision>
      <origin xyz="0 0 0" rpy="0 0 0" />
      <geometry>
        <mesh filename="package://adam_description/urdf/adam_u/meshes/R_ring_distal.dae" />
      </geometry>
    </collision>
  </link>
  <joint name="R_ring_DIP_joint" type="revolute">
    <origin xyz="0 0.0304449999999941 0.0102750000000099" rpy="0.0397480000000075 0 0" />
    <parent link="R_ring_proximal" />
    <child link="R_ring_distal" />
    <axis xyz="1 0 0" />
    <limit lower="0" upper="1.6" effort="1.0" velocity="1" />
  </joint>
  <link name="R_pinky_proximal">
    <inertial>
      <origin xyz="0.00788897714502957 0.0133869227067238 0.00101141410835032" rpy="0 0 0" />
      <mass value="0.00701853182876559" />
      <inertia ixx="8.95729441425343E-07" ixy="-1.18146961917887E-11" ixz="-3.54915778627984E-12"
        iyy="2.8382915120387E-07" iyz="-7.44730775821664E-08" izz="8.24848125349754E-07" />
    </inertial>
    <visual>
      <origin xyz="0 0 0" rpy="0 0 0" />
      <geometry>
        <mesh filename="package://adam_description/urdf/adam_u/meshes/R_pinky_proximal.dae" />
      </geometry>
      <material name="">
        <color rgba="0.752941176470588 0.752941176470588 0.752941176470588 1" />
      </material>
    </visual>
    <collision>
      <origin xyz="0 0 0" rpy="0 0 0" />
      <geometry>
        <mesh filename="package://adam_description/urdf/adam_u/meshes/R_pinky_proximal.dae" />
      </geometry>
    </collision>
  </link>
  <joint name="R_pinky_MCP_joint" type="revolute">
    <origin xyz="-0.039300893999997 -2.84830000677194E-05 -0.124262588999974"
      rpy="-1.82078530717921 0.10472 0" />
    <parent link="wristRollRight" />
    <child link="R_pinky_proximal" />
    <axis xyz="1 0 0" />
    <limit lower="0" upper="1.7" effort="1.0" velocity="1" />
  </joint>
  <link name="R_pinky_distal">
    <inertial>
      <origin xyz="0.00791918669793035 0.0166368770905698 -0.00279124266185325" rpy="0 0 0" />
      <mass value="0.00357986960061578" />
      <inertia ixx="4.28296885217303E-07" ixy="-6.19911495396114E-10" ixz="-3.02772463164244E-10"
        iyy="8.81645541081828E-08" iyz="-9.44288810237396E-08" izz="3.95700008437022E-07" />
    </inertial>
    <visual>
      <origin xyz="0 0 0" rpy="0 0 0" />
      <geometry>
        <mesh filename="package://adam_description/urdf/adam_u/meshes/R_pinky_distal.dae" />
      </geometry>
      <material name="">
        <color rgba="0.752941176470588 0.752941176470588 0.752941176470588 1" />
      </material>
    </visual>
    <collision>
      <origin xyz="0 0 0" rpy="0 0 0" />
      <geometry>
        <mesh filename="package://adam_description/urdf/adam_u/meshes/R_pinky_distal.dae" />
      </geometry>
    </collision>
  </link>
  <joint name="R_pinky_DIP_joint" type="revolute">
    <origin xyz="0 0.0304450000000081 0.0102750000001108" rpy="-0.0376910000000213 0 0" />
    <parent link="R_pinky_proximal" />
    <child link="R_pinky_distal" />
    <axis xyz="1 0 0" />
    <limit lower="0" upper="1.6" effort="1.0" velocity="1" />
  </joint>
  <link name="neckYaw">
    <inertial>
      <origin xyz="0.0098522444285089 6.58333443519493E-06 0.0533101867871305" rpy="0 0 0" />
      <mass value="2.4885790258433E-05" />
      <inertia ixx="5.20642252056383E-10" ixy="1.99480465686937E-15" ixz="-1.8320372300871E-11"
        iyy="6.86475581231107E-10" iyz="-1.05719803209352E-14" izz="1.11412705808525E-09" />
    </inertial>
    <visual>
      <origin xyz="0 0 0" rpy="0 0 0" />
      <geometry>
        <mesh filename="package://adam_description/urdf/adam_u/meshes/neckYaw.STL" />
      </geometry>
      <material name="">
        <color rgba="1 1 1 1" />
      </material>
    </visual>
    <collision>
      <origin xyz="0 0 0" rpy="0 0 0" />
      <geometry>
        <mesh filename="package://adam_description/urdf/adam_u/meshes/neckYaw.STL" />
      </geometry>
    </collision>
  </link>
  <joint name="neckYaw" type="revolute">
    <origin xyz="-0.012999999999999 0 0.298550000000002" rpy="0 0 0" />
    <parent link="torso" />
    <child link="neckYaw" />
    <axis xyz="0 0 1" />
    <limit effort="6.4" lower="-1.4" upper="1.4" velocity="5" />
  </joint>
  <link name="neckPitch">
    <inertial>
      <origin xyz="0.0222675085135259 -0.0200403867537856 0.0446667787578988" rpy="0 0 0" />
      <mass value="0.634136883610143" />
      <inertia ixx="0.00180767250576403" ixy="-2.35667145632258E-06" ixz="0.000142787551531224"
        iyy="0.00191410441227569" iyz="2.97282143280428E-07" izz="0.00213544942831017" />
    </inertial>
    <visual>
      <origin xyz="0 0 0" rpy="0 0 0" />
      <geometry>
        <mesh filename="package://adam_description/urdf/adam_u/meshes/neckPitch.STL" />
      </geometry>
      <material name="">
        <color rgba="1 1 1 1" />
      </material>
    </visual>
    <collision>
      <origin xyz="0 0 0" rpy="0 0 0" />
      <geometry>
        <mesh filename="package://adam_description/urdf/adam_u/meshes/neckPitch.STL" />
      </geometry>
    </collision>
  </link>
  <joint name="neckPitch" type="revolute">
    <origin xyz="0.031600000000006 0.0200000014051488 0.145949999999987" rpy="0 0 0" />
    <parent link="neckYaw" />
    <child link="neckPitch" />
    <axis xyz="0 1 0" />
    <limit effort="6.4" lower="-0.77" upper="0.77" velocity="5" />
  </joint>

  <link name="L_hand_noitom_bvh_link" />
  <link name="L_NOITOM_HAND" />

  <joint name="L_hand_noitom_bvh_joint" type="fixed">
    <origin rpy="-1.5707963705 0.0000000000 -1.5707963705"
      xyz="0.0000000000 -0.0199999774 -0.0799999842" />
    <parent link="wristRollLeft" />
    <child link="L_hand_noitom_bvh_link" />
  </joint>
  <joint name="L_NOITOM_HAND_JOINT" type="fixed">
    <origin rpy="-0.0000000000 1.5707962831 0.0000000000"
      xyz="0.0000000000 -0.0199999774 -0.0799999842" />
    <parent link="wristRollLeft" />
    <child link="L_NOITOM_HAND" />
  </joint>

  <link name="R_hand_noitom_bvh_link" />
  <link name="R_NOITOM_HAND" />

  <joint name="R_noitom_hand_joint" type="fixed">
    <origin rpy="-3.1415925662 -1.5707962513 0.0000000000"
      xyz="-0.0000000000 0.0199999923 -0.0799999842" />
    <parent link="wristRollRight" />
    <child link="R_NOITOM_HAND" />
  </joint>
  <joint name="R_hand_noitom_bvh_joint" type="fixed">
    <origin rpy="-1.5707963705 0.0000000000 -1.5707963705"
      xyz="-0.0000000000 0.0199999923 -0.0799999842" />
    <parent link="wristRollRight" />
    <child link="R_hand_noitom_bvh_link" />
  </joint>
</robot>